Workbook

Sheet Empresas Inadimplentes
A2: Indicador Serasa Experian de Inadimplência das Empresas
A3: Mês | B3: Empresas Inadimplentes (milhões) | C3: Dívidas Negativadas (milhões) | D3: Dívidas Negativadas (R$ bilhões) | E3: Dívida Média (por CNPJ) | F3: Dívida Média (R$) | G3: Ticket Médio (R$)
A4: 45292 | B4: 6.664598 | C4: 47.241986 | D4: 127.79893 | E4: =C4/B4 -> 7.0884975 | F4: =1000*D4/B4 -> 19175.789 | G4: =F4/E4 -> 2705.198
A5: 45323 | B5: 6.647361 | C5: 47.362865 | D5: 130.03723 | E5: =C5/B5 -> 7.1250629 | F5: =1000*D5/B5 -> 19562.234 | G5: =F5/E5 -> 2745.5524
A6: 45352 | B6: 6.671568 | C6: 48.103889 | D6: 134.00421 | E6: =C6/B6 -> 7.2102824 | F6: =1000*D6/B6 -> 20085.865 | G6: =F6/E6 -> 2785.7252
A7: 45383 | B7: 6.738891 | C7: 48.782654 | D7: 138.22259 | E7: =C7/B7 -> 7.2389736 | F7: =1000*D7/B7 -> 20511.177 | G7: =F7/E7 -> 2833.4372
A8: 45413 | B8: 6.866723 | C8: 49.755541 | D8: 143.87668 | E8: =C8/B8 -> 7.2458931 | F8: =1000*D8/B8 -> 20952.742 | G8: =F8/E8 -> 2891.6715
A9: 45444 | B9: 6.914462 | C9: 49.967276 | D9: 146.24886 | E9: =C9/B9 -> 7.2264879 | F9: =1000*D9/B9 -> 21151.155 | G9: =F9/E9 -> 2926.8927
A10: 45474 | B10: 6.900429 | C10: 49.890072 | D10: 147.14698 | E10: =C10/B10 -> 7.2299957 | F10: =1000*D10/B10 -> 21324.323 | G10: =F10/E10 -> 2949.4241
A11: 45505 | B11: 6.875258 | C11: 50.087444 | D11: 149.12995 | E11: =C11/B11 -> 7.285173 | F11: =1000*D11/B11 -> 21690.815 | G11: =F11/E11 -> 2977.3918
A12: 45536 | B12: 6.907592 | C12: 50.592664 | D12: 151.90167 | E12: =C12/B12 -> 7.3242114 | F12: =1000*D12/B12 -> 21990.539 | G12: =F12/E12 -> 3002.4447
A13: 45566 | B13: 6.965474 | C13: 51.33853 | D13: 156.1466 | E13: =C13/B13 -> 7.3704288 | F13: =1000*D13/B13 -> 22417.225 | G13: =F13/E13 -> 3041.5089
A14: 45597 | B14: 6.959131 | C14: 50.42147 | D14: 153.35608 | E14: =C14/B14 -> 7.2453687 | F14: =1000*D14/B14 -> 22036.671 | G14: =F14/E14 -> 3041.4838
A15: 45627 | B15: 6.948754 | C15: 50.175794 | D15: 150.63588 | E15: =C15/B15 -> 7.2208333 | F15: =1000*D15/B15 -> 21678.113 | G15: =F15/E15 -> 3002.1623
... A22: 45839 | B22: 7.998788 | C22: 58.573977 | D22: 193.4284 | E22: =C22/B22 -> 7.3228565 | F22: =1000*D22/B22 -> 24182.213 | G22: =F22/E22 -> 3302.2923
A23: 45870 | B23: 8.113622 | C23: 59.850641 | D23: 199.84863 | E23: =IFERROR(C23/B23,"") -> 7.3765626 | F23: =IFERROR(1000*D23/B23,"") -> 24631.248 | G23: =IFERROR(F23/E23,"") -> 3339.1227
A24: 45901 | B24: 8.379799 | C24: 60.558393 | D24: 201.73968 | E24: =IFERROR(C24/B24,"") -> 7.2267119 | F24: =IFERROR(1000*D24/B24,"") -> 24074.525 | G24: =IFERROR(F24/E24,"") -> 3331.3249
A25: 45931 | B25: 8.657024 | C25: 61.513324 | D25: 204.81428 | E25: =IFERROR(C25/B25,"") -> 7.105597 | F25: =IFERROR(1000*D25/B25,"") -> 23658.74 | G25: =IFERROR(F25/E25,"") -> 3329.5922
A26: 45962 | B26: 8.861181 | C26: 62.455932 | D26: 210.81469 | E26: =IFERROR(C26/B26,"") -> 7.0482628 | F26: =IFERROR(1000*D26/B26,"") -> 23790.812 | G26: =IFERROR(F26/E26,"") -> 3375.415
A27: 45992 | B27: 8.941279 | C27: 62.989977 | D27: 212.96568 | E27: =IFERROR(C27/B27,"") -> 7.0448509 | F27: =IFERROR(1000*D27/B27,"") -> 23818.257 | G27: =IFERROR(F27/E27,"") -> 3380.9456
A28: 46023 | B28: 8.719238 | C28: 60.115683 | D28: 201.74918 | E28: =IFERROR(C28/B28,"") -> 6.8946028 | F28: =IFERROR(1000*D28/B28,"") -> 23138.396 | G28: =IFERROR(F28/E28,"") -> 3356.0158
A29: 46054 | B29: 8.81191 | C29: 60.697113 | D29: 204.58126 | E29: =IFERROR(C29/B29,"") -> 6.8880768 | F29: =IFERROR(1000*D29/B29,"") -> 23216.449 | G29: =IFERROR(F29/E29,"") -> 3370.527
A30: 46082 | B30: 8.870845 | C30: 62.031575 | D30: 212.83795 | E30: =IFERROR(C30/B30,"") -> 6.992747 | F30: =IFERROR(1000*D30/B30,"") -> 23992.973 | G30: =IFERROR(F30/E30,"") -> 3431.1228
A31: 46113 | B31: 8.957247 | C31: 63.689682 | D31: 220.93865 | E31: =IFERROR(C31/B31,"") -> 7.1104081 | F31: =IFERROR(1000*D31/B31,"") -> 24665.91 | G31: =IFERROR(F31/E31,"") -> 3468.9865
A32: 46143 | B32: 9.01603 | C32: 65.382979 | D32: 229.85536 | E32: =IFERROR(C32/B32,"") -> 7.2518591 | F32: =IFERROR(1000*D32/B32,"") -> 25494.077 | G32: =IFERROR(F32/E32,"") -> 3515.5229
A33: 46174 | B33: 9.130291 | C33: 66.245555 | D33: 232.90419 | E33: =IFERROR(C33/B33,"") -> 7.2555798 | F33: =IFERROR(1000*D33/B33,"") -> 25508.956 | G33: =IFERROR(F33/E33,"") -> 3515.7709
A34: 46204 | B34: 9.183684 | C34: 67.188903 | D34: 238.62775 | E34: =IFERROR(C34/B34,"") -> 7.3161166 | F34: =IFERROR(1000*D34/B34,"") -> 25983.881 | G34: =IFERROR(F34/E34,"") -> 3551.5947
A35: 46235
A36: 46266
A37: 46296
A38: 46327
A39: 46357

Sheet Setores Negativados
A2: Indicador Serasa Experian de Inadimplência das Empresas - Setor da Empresa Negativada (%)
A3: Mês | B3: Comércio | C3: Serviços | D3: Indústria | E3: Primário | F3: Outros
A4: 45292 | B4: 0.36379028 | C4: 0.51884428 | D4: 0.075095902 | E4: 0.0081292225 | F4: 0.034140313
A5: 45323 | B5: 0.36275418 | C5: 0.51997474 | D5: 0.074991263 | E5: 0.0081475942 | F5: 0.034132216
A6: 45352 | B6: 0.36177357 | C6: 0.52094895 | D6: 0.074984471 | E6: 0.0081911778 | F6: 0.034101824
A7: 45383 | B7: 0.35999336 | C7: 0.52373898 | D7: 0.074618064 | E7: 0.0079665927 | F7: 0.033683003
A8: 45413 | B8: 0.35913783 | C8: 0.52567877 | D8: 0.073879782 | E8: 0.0078763917 | F8: 0.033427222
A9: 45444 | B9: 0.35739975 | C9: 0.52770567 | D9: 0.073551782 | E9: 0.0078227344 | F9: 0.033520059
A10: 45474 | B10: 0.35649986 | C10: 0.52888972 | D10: 0.073435724 | E10: 0.0077024197 | F10: 0.033472271
A11: 45505 | B11: 0.35613558 | C11: 0.52956375 | D11: 0.073224452 | E11: 0.0076471312 | F11: 0.03342909
A12: 45536 | B12: 0.35556414 | C12: 0.53032793 | D12: 0.073073656 | E12: 0.0075926604 | F12: 0.03344161
A13: 45566 | B13: 0.35437847 | C13: 0.53176279 | D13: 0.072864675 | E13: 0.0075660321 | F13: 0.033428035
A14: 45597 | B14: 0.35560144 | C14: 0.52147014 | D14: 0.080136442 | E14: 0.009905116 | F14: 0.032886865
A15: 45627 | B15: 0.35443246 | C15: 0.52241956 | D15: 0.07988425 | E15: 0.0099440849 | F15: 0.033319643
... A34: 46204 | B34: 0.32144987 | C34: 0.55799024 | D34: 0.080255375 | E34: 0.0095546624 | F34: 0.03074986
A35: 46235
A36: 46266
A37: 46296
A38: 46327
A39: 46357

Sheet Setores
A2: Indicador Serasa Experian de Inadimplência das Empresas - Participação dos Setores na Inadimplência Total (%)
A3: Mês | B3: Bancos / Cartões (A) | C3: Utilities (B) | D3: Telefonia (C) | E3: Varejo (D) | F3: Serviços (E) | G3: Financeiras (F) | H3: Securitizadoras (G) | I3: Cooperativas (H) | J3: Outros (I) | K3: Total Financeiro (A) + (F) | L3: Total não Financeiro (B) + (C) + (D) + (E) + (G) + (H) + (I)
A4: 45292 | B4: 0.20531435 | C4: 0.075058519 | D4: 0.072529456 | E4: 0.039169161 | F4: 0.27942328 | G4: 0.032717123 | H4: 0.0097662683 | I4: n.d. | J4: 0.28602185 | K4: =G4+B4 -> 0.23803147 | L4: =SUM(C4:F4)+H4+J4 -> 0.76196853
A5: 45323 | B5: 0.20820338 | C5: 0.073936207 | D5: 0.071301589 | E5: 0.039022408 | F5: 0.28018657 | G5: 0.03247909 | H5: 0.0096256888 | I5: n.d. | J5: 0.28524506 | K5: =G5+B5 -> 0.24068247 | L5: =SUM(C5:F5)+H5+J5 -> 0.75931753
A6: 45352 | B6: 0.20793209 | C6: 0.073350901 | D6: 0.069231669 | E6: 0.038370529 | F6: 0.28061264 | G6: 0.032352898 | H6: 0.0092962954 | I6: n.d. | J6: 0.28885297 | K6: =G6+B6 -> 0.24028499 | L6: =SUM(C6:F6)+H6+J6 -> 0.75971501
A7: 45383 | B7: 0.21103721 | C7: 0.069380613 | D7: 0.06811604 | E7: 0.037510569 | F7: 0.28406577 | G7: 0.034167737 | H7: 0.009094877 | I7: n.d. | J7: 0.28662718 | K7: =G7+B7 -> 0.24520495 | L7: =SUM(C7:F7)+H7+J7 -> 0.75479505
A8: 45413 | B8: 0.21025077 | C8: 0.068584967 | D8: 0.067006141 | E8: 0.037397527 | F8: 0.2854532 | G8: 0.034499546 | H8: 0.0089304317 | I8: n.d. | J8: 0.28787742 | K8: =G8+B8 -> 0.24475032 | L8: =SUM(C8:F8)+H8+J8 -> 0.75524968
A9: 45444 | B9: 0.21360586 | C9: 0.068476557 | D9: 0.069530113 | E9: 0.036817899 | F9: 0.2857955 | G9: 0.033441478 | H9: 0.0087880952 | I9: n.d. | J9: 0.28354449 | K9: =G9+B9 -> 0.24704734 | L9: =SUM(C9:F9)+H9+J9 -> 0.75295266
A10: 45474 | B10: 0.20641873 | C10: 0.068628143 | D10: 0.068825629 | E10: 0.036916563 | F10: 0.28815376 | G10: 0.033728543 | H10: 0.0087061845 | I10: n.d. | J10: 0.28862244 | K10: =G10+B10 -> 0.24014728 | L10: =SUM(C10:F10)+H10+J10 -> 0.75985272
A11: 45505 | B11: 0.20643129 | C11: 0.069839405 | D11: 0.075569371 | E11: 0.037370737 | F11: 0.31245343 | G11: 0.03088459 | H11: 0.0072605017 | I11: 0.073839423 | J11: 0.18635125 | K11: =G11+B11 -> 0.23731588 | L11: =SUM(C11:F11)+H11+I11+J11 -> 0.76268412
A12: 45536 | B12: 0.20946021 | C12: 0.070544743 | D12: 0.074820177 | E12: 0.037119201 | F12: 0.3093773 | G12: 0.030703473 | H12: 0.0071383988 | I12: 0.074445104 | J12: 0.1863914 | K12: =G12+B12 -> 0.24016369 | L12: =SUM(C12:F12)+H12+I12+J12 -> 0.75983631
A13: 45566 | B13: 0.21051302 | C13: 0.069675927 | D13: 0.072877543 | E13: 0.036577677 | F13: 0.31003386 | G13: 0.030749869 | H13: 0.0078690351 | I13: 0.07585583 | J13: 0.18584723 | K13: =G13+B13 -> 0.24126289 | L13: =SUM(C13:F13)+H13+I13+J13 -> 0.75873711
A14: 45597 | B14: 0.21444833 | C14: 0.063230724 | D14: 0.072866062 | E14: 0.037193017 | F14: 0.31122334 | G14: 0.031343851 | H14: 0.0076446758 | I14: 0.076537351 | J14: 0.18551265 | K14: =G14+B14 -> 0.24579218 | L14: =SUM(C14:F14)+H14+I14+J14 -> 0.75420782
A15: 45627 | B15: 0.20149333 | C15: 0.070765637 | D15: 0.074008939 | E15: 0.036717857 | F15: 0.31575839 | G15: 0.031710861 | H15: 0.0074493052 | I15: 0.07649408 | J15: 0.1856016 | K15: =G15+B15 -> 0.23320419 | L15: =SUM(C15:F15)+H15+I15+J15 -> 0.76679581
A16: 45658 | B16: 0.20470593 | C16: 0.068402388 | D16: 0.071865079 | E16: 0.036161976 | F16: 0.31686459 | G16: 0.031725686 | H16: 0.0071971764 | I16: 0.077524035 | J16: 0.18555313 | K16: =G16+B16 -> 0.23643162 | L16: =SUM(C16:F16)+H16+I16+J16 -> 0.76356838
A17: 45689 | B17: 0.20451147 | C17: 0.066163293 | D17: 0.070613632 | E17: 0.036070491 | F17: 0.31635222 | G17: 0.031976709 | H17: 0.011290239 | I17: 0.078670005 | J17: 0.18435194 | K17: =G17+B17 -> 0.23648818 | L17: =SUM(C17:F17)+H17+I17+J17 -> 0.76351182
A18: 45717 | B18: 0.20738079 | C18: 0.066696164 | D18: 0.069895736 | E18: 0.036199118 | F18: 0.31687723 | G18: 0.031970627 | H18: 0.0067675808 | I18: 0.080278797 | J18: 0.18393396 | K18: =G18+B18 -> 0.23935142 | L18: =SUM(C18:F18)+H18+I18+J18 -> 0.76064858
A19: 45748 | B19: 0.20813695 | C19: 0.066126705 | D19: 0.067931959 | E19: 0.03501772 | F19: 0.31566082 | G19: 0.034249318 | H19: 0.007687467 | I19: 0.081242802 | J19: 0.18394625 | K19: =G19+B19 -> 0.24238627 | L19: =SUM(C19:F19)+H19+I19+J19 -> 0.75761373
A20: 45778 | B20: 0.20870156 | C20: 0.066825284 | D20: 0.067856596 | E20: 0.034610119 | F20: 0.31538741 | G20: 0.035122115 | H20: 0.0075585004 | I20: 0.081360252 | J20: 0.18257817 | K20: =G20+B20 -> 0.24382368 | L20: =SUM(C20:F20)+H20+I20+J20 -> 0.75617632
A21: 45809 | B21: 0.19668977 | C21: 0.069007727 | D21: 0.067057044 | E21: 0.034850161 | F21: 0.31827001 | G21: 0.036399053 | H21: 0.010112879 | I21: 0.08368307 | J21: 0.18393028 | K21: =G21+B21 -> 0.23308882 | L21: =SUM(C21:F21)+H21+I21+J21 -> 0.76691118
A22: 45839 | B22: 0.19777874 | C22: 0.068632033 | D22: 0.066252699 | E22: 0.034283461 | F22: 0.31774791 | G22: 0.037395504 | H22: 0.0098806242 | I22: 0.084361353 | J22: 0.18366768 | K22: =G22+B22 -> 0.23517424 | L22: =SUM(C22:F22)+H22+I22+J22 -> 0.76482576
... A33: 46174 | B33: 0.19473782 | C33: 0.069314632 | D33: 0.059963841 | E33: 0.03321034 | F33: 0.31600929 | G33: 0.045129125 | H33: 0.016382597 | I33: 0.083622295 | J33: 0.18163006 | K33: =G33+B33 -> 0.23986695 | L33: =SUM(C33:F33)+H33+I33+J33 -> 0.76013305
A34: 46204 | B34: 0.1965615 | C34: 0.068503561 | D34: 0.061707696 | E34: 0.0331484 | F34: 0.31673136 | G34: 0.046350816 | H34: 0.011323971 | I34: 0.084651352 | J34: 0.18102134 | K34: 0.24291232 | L34: 0.75708768
A35: 46235
A36: 46266
A37: 46296
A38: 46327
A39: 46357

Sheet MPM
A2: Indicador Serasa Experian de Inadimplência das Empresas
A3: Micro, Pequenas e Médias Empresas
A4: Mês | B4: Empresas Inadimplentes (milhões) | C4: Dívidas Negativadas (milhões) | D4: Dívidas Negativadas (R$ bilhões) | E4: Dívida Média (por CNPJ) | F4: Dívida Média (R$) | G4: Ticket Médio (R$)
A5: 45292 | B5: ='Micro e Pequenas'!B5+Médias!B5 -> 6.314924 | C5: ='Micro e Pequenas'!C5+Médias!C5 -> 43.690007 | D5: ='Micro e Pequenas'!D5+Médias!D5 -> 114.23599 | E5: =C5/B5 -> 6.9185325 | F5: =1000*D5/B5 -> 18089.844 | G5: =F5/E5 -> 2614.6939
A6: 45323 | B6: ='Micro e Pequenas'!B6+Médias!B6 -> 6.29938 | C6: ='Micro e Pequenas'!C6+Médias!C6 -> 43.80181 | D6: ='Micro e Pequenas'!D6+Médias!D6 -> 116.31858 | E6: =C6/B6 -> 6.9533526 | F6: =1000*D6/B6 -> 18465.084 | G6: =F6/E6 -> 2655.5656
A7: 45352 | B7: ='Micro e Pequenas'!B7+Médias!B7 -> 6.322353 | C7: ='Micro e Pequenas'!C7+Médias!C7 -> 44.491119 | D7: ='Micro e Pequenas'!D7+Médias!D7 -> 119.93361 | E7: =C7/B7 -> 7.037114 | F7: =1000*D7/B7 -> 18969.775 | G7: =F7/E7 -> 2695.6753
A8: 45383 | B8: ='Micro e Pequenas'!B8+Médias!B8 -> 6.388012 | C8: ='Micro e Pequenas'!C8+Médias!C8 -> 45.116023 | D8: ='Micro e Pequenas'!D8+Médias!D8 -> 123.8712 | E8: =C8/B8 -> 7.0626077 | F8: =1000*D8/B8 -> 19391.197 | G8: =F8/E8 -> 2745.6144
A9: 45413 | B9: ='Micro e Pequenas'!B9+Médias!B9 -> 6.513265 | C9: ='Micro e Pequenas'!C9+Médias!C9 -> 46.027344 | D9: ='Micro e Pequenas'!D9+Médias!D9 -> 129.04271 | E9: =C9/B9 -> 7.0667083 | F9: =1000*D9/B9 -> 19812.292 | G9: =F9/E9 -> 2803.6096
A10: 45444 | B10: ='Micro e Pequenas'!B10+Médias!B10 -> 6.55849 | C10: ='Micro e Pequenas'!C10+Médias!C10 -> 46.205231 | D10: ='Micro e Pequenas'!D10+Médias!D10 -> 131.21268 | E10: =C10/B10 -> 7.045102 | F10: =1000*D10/B10 -> 20006.538 | G10: =F10/E10 -> 2839.7797
A11: 45474 | B11: ='Micro e Pequenas'!B11+Médias!B11 -> 6.54724 | C11: ='Micro e Pequenas'!C11+Médias!C11 -> 46.122845 | D11: ='Micro e Pequenas'!D11+Médias!D11 -> 131.99046 | E11: =C11/B11 -> 7.0446241 | F11: =1000*D11/B11 -> 20159.71 | G11: =F11/E11 -> 2861.7154
A12: 45505 | B12: ='Micro e Pequenas'!B12+Médias!B12 -> 6.523154 | C12: ='Micro e Pequenas'!C12+Médias!C12 -> 46.320533 | D12: ='Micro e Pequenas'!D12+Médias!D12 -> 133.86164 | E12: =C12/B12 -> 7.1009412 | F12: =1000*D12/B12 -> 20520.999 | G12: =F12/E12 -> 2889.8985
A13: 45536 | B13: ='Micro e Pequenas'!B13+Médias!B13 -> 6.55408 | C13: ='Micro e Pequenas'!C13+Médias!C13 -> 46.785089 | D13: ='Micro e Pequenas'!D13+Médias!D13 -> 136.39812 | E13: =C13/B13 -> 7.1383152 | F13: =1000*D13/B13 -> 20811.176 | G13: =F13/E13 -> 2915.4185
A14: 45566 | B14: ='Micro e Pequenas'!B14+Médias!B14 -> 6.610262 | C14: ='Micro e Pequenas'!C14+Médias!C14 -> 47.479363 | D14: ='Micro e Pequenas'!D14+Médias!D14 -> 140.35833 | E14: =C14/B14 -> 7.1826749 | F14: =1000*D14/B14 -> 21233.399 | G14: =F14/E14 -> 2956.1966
A15: 45597 | B15: ='Micro e Pequenas'!B15+Médias!B15 -> 6.605747 | C15: ='Micro e Pequenas'!C15+Médias!C15 -> 46.642104 | D15: ='Micro e Pequenas'!D15+Médias!D15 -> 137.93676 | E15: =C15/B15 -> 7.0608372 | F15: =1000*D15/B15 -> 20881.327 | G15: =F15/E15 -> 2957.3444
A16: 45627 | B16: ='Micro e Pequenas'!B16+Médias!B16 -> 6.587152 | C16: ='Micro e Pequenas'!C16+Médias!C16 -> 46.288729 | D16: ='Micro e Pequenas'!D16+Médias!D16 -> 134.803 | E16: =C16/B16 -> 7.0271233 | F16: =1000*D16/B16 -> 20464.534 | G16: =F16/E16 -> 2912.2208
... A35: 46204 | B35: ='Micro e Pequenas'!B35+Médias!B35 -> 8.774063 | C35: ='Micro e Pequenas'!C35+Médias!C35 -> 61.887905 | D35: ='Micro e Pequenas'!D35+Médias!D35 -> 214.74248 | E35: =C35/B35 -> 7.0535059 | F35: =1000*D35/B35 -> 24474.691 | G35: =F35/E35 -> 3469.8619
A36: 46235
A37: 46266
A38: 46296
A39: 46327
A40: 46357

Sheet Micro e Pequenas
A2: Indicador Serasa Experian de Inadimplência das Empresas
A3: Micro e Pequenas Empresas
A4: Mês | B4: Empresas Inadimplentes (milhões) | C4: Dívidas Negativadas (milhões) | D4: Dívidas Negativadas (R$ bilhões) | E4: Dívida Média (por CNPJ) | F4: Dívida Média (R$) | G4: Ticket Médio (R$)
A5: 45292 | B5: 6.28703 | C5: 42.928638 | D5: 109.96983 | E5: =C5/B5 -> 6.8281268 | F5: =1000*D5/B5 -> 17491.539 | G5: =F5/E5 -> 2561.6893
A6: 45323 | B6: 6.27117 | C6: 43.013866 | D6: 111.85709 | E6: =C6/B6 -> 6.8589858 | F6: =1000*D6/B6 -> 17836.718 | G6: =F6/E6 -> 2600.4891
A7: 45352 | B7: 6.292915 | C7: 43.626491 | D7: 114.96715 | E7: =C7/B7 -> 6.9326363 | F7: =1000*D7/B7 -> 18269.299 | G7: =F7/E7 -> 2635.26
A8: 45383 | B8: 6.358354 | C8: 44.211238 | D8: 118.6237 | E8: =C8/B8 -> 6.9532521 | F8: =1000*D8/B8 -> 18656.354 | G8: =F8/E8 -> 2683.1119
A9: 45413 | B9: 6.483105 | C9: 45.072625 | D9: 123.45917 | E9: =C9/B9 -> 6.9523207 | F9: =1000*D9/B9 -> 19043.216 | G9: =F9/E9 -> 2739.1165
A10: 45444 | B10: 6.528334 | C10: 45.262642 | D10: 125.65134 | E10: =C10/B10 -> 6.9332608 | F10: =1000*D10/B10 -> 19247.076 | G10: =F10/E10 -> 2776.0497
A11: 45474 | B11: 6.516997 | C11: 45.177116 | D11: 126.38402 | E11: =C11/B11 -> 6.9321984 | F11: =1000*D11/B11 -> 19392.984 | G11: =F11/E11 -> 2797.5229
A12: 45505 | B12: 6.492755 | C12: 45.347965 | D12: 128.09117 | E12: =C12/B12 -> 6.9843949 | F12: =1000*D12/B12 -> 19728.323 | G12: =F12/E12 -> 2824.6288
A13: 45536 | B13: 6.523265 | C13: 45.79476 | D13: 130.50246 | E13: =C13/B13 -> 7.0202207 | F13: =1000*D13/B13 -> 20005.697 | G13: =F13/E13 -> 2849.7248
A14: 45566 | B14: 6.578951 | C14: 46.441845 | D14: 134.10779 | E14: =C14/B14 -> 7.0591565 | F14: =1000*D14/B14 -> 20384.374 | G14: =F14/E14 -> 2887.65
A15: 45597 | B15: 6.573635 | C15: 45.628834 | D15: 131.81446 | E15: =C15/B15 -> 6.9411876 | F15: =1000*D15/B15 -> 20051.989 | G15: =F15/E15 -> 2888.8413
A16: 45627 | B16: 6.558468 | C16: 45.493251 | D16: 130.01334 | E16: =C16/B16 -> 6.9365667 | F16: =1000*D16/B16 -> 19823.736 | G16: =F16/E16 -> 2857.8599
... A35: 46204 | B35: 8.736804 | C35: 60.510699 | D35: 205.96433 | E35: =C35/B35 -> 6.9259536 | F35: =1000*D35/B35 -> 23574.333 | G35: =F35/E35 -> 3403.7671
A36: 46235
A37: 46266
A38: 46296
A39: 46327
A40: 46357

Sheet Médias
A2: Indicador Serasa Experian de Inadimplência das Empresas
A3: Médias Empresas
A4: Mês | B4: Empresas Inadimplentes (milhões) | C4: Dívidas Negativadas (milhões) | D4: Dívidas Negativadas (R$ bilhões) | E4: Dívida Média (por CNPJ) | F4: Dívida Média (R$) | G4: Ticket Médio (R$)
A5: 45292 | B5: 0.027894 | C5: 0.761369 | D5: 4.2661617 | E5: =C5/B5 -> 27.295081 | F5: =1000*D5/B5 -> 152941.91 | G5: =F5/E5 -> 5603.2773
A6: 45323 | B6: 0.02821 | C6: 0.787944 | D6: 4.4614912 | E6: =C6/B6 -> 27.931372 | F6: =1000*D6/B6 -> 158152.82 | G6: =F6/E6 -> 5662.1932
A7: 45352 | B7: 0.029438 | C7: 0.864628 | D7: 4.9664656 | E7: =C7/B7 -> 29.371153 | F7: =1000*D7/B7 -> 168709.34 | G7: =F7/E7 -> 5744.049
A8: 45383 | B8: 0.029658 | C8: 0.904785 | D8: 5.2475001 | E8: =C8/B8 -> 30.507283 | F8: =1000*D8/B8 -> 176933.71 | G8: =F8/E8 -> 5799.7205
A9: 45413 | B9: 0.03016 | C9: 0.954719 | D9: 5.5835345 | E9: =C9/B9 -> 31.655139 | F9: =1000*D9/B9 -> 185130.45 | G9: =F9/E9 -> 5848.3538
A10: 45444 | B10: 0.030156 | C10: 0.942589 | D10: 5.5613367 | E10: =C10/B10 -> 31.257096 | F10: =1000*D10/B10 -> 184418.91 | G10: =F10/E10 -> 5900.0654
A11: 45474 | B11: 0.030243 | C11: 0.945729 | D11: 5.6064414 | E11: =C11/B11 -> 31.271005 | F11: =1000*D11/B11 -> 185379.8 | G11: =F11/E11 -> 5928.1691
A12: 45505 | B12: 0.030399 | C12: 0.972568 | D12: 5.7704733 | E12: =C12/B12 -> 31.993421 | F12: =1000*D12/B12 -> 189824.44 | G12: =F12/E12 -> 5933.2337
A13: 45536 | B13: 0.030815 | C13: 0.990329 | D13: 5.8956513 | E13: =C13/B13 -> 32.137887 | F13: =1000*D13/B13 -> 191324.07 | G13: =F13/E13 -> 5953.225
A14: 45566 | B14: 0.031311 | C14: 1.037518 | D14: 6.2505351 | E14: =C14/B14 -> 33.135895 | F14: =1000*D14/B14 -> 199627.45 | G14: =F14/E14 -> 6024.5076
A15: 45597 | B15: 0.032112 | C15: 1.01327 | D15: 6.1223042 | E15: =C15/B15 -> 31.554248 | F15: =1000*D15/B15 -> 190654.71 | G15: =F15/E15 -> 6042.1252
A16: 45627 | B16: 0.028684 | C16: 0.795478 | D16: 4.7896632 | E16: =C16/B16 -> 27.732464 | F16: =1000*D16/B16 -> 166980.31 | G16: =F16/E16 -> 6021.1134
... A35: 46204 | B35: 0.037259 | C35: 1.377206 | D35: 8.7781544 | E35: =C35/B35 -> 36.963042 | F35: =1000*D35/B35 -> 235598.23 | G35: =F35/E35 -> 6373.8863
A36: 46235
A37: 46266
A38: 46296
A39: 46327
A40: 46357

Sheet Grandes
A2: Indicador Serasa Experian de Inadimplência das Empresas
A3: Grandes Empresas
A4: Mês | B4: Empresas Inadimplentes (milhões) | C4: Dívidas Negativadas (milhões) | D4: Dívidas Negativadas (R$ bilhões) | E4: Dívida Média (por CNPJ) | F4: Dívida Média (R$) | G4: Ticket Médio (R$)
A5: 45292 | B5: 0.020219 | C5: 1.149551 | D5: 5.6294818 | E5: =C5/B5 -> 56.854988 | F5: =1000*D5/B5 -> 278425.33 | G5: =F5/E5 -> 4897.1135
A6: 45323 | B6: 0.020304 | C6: 1.158635 | D6: 5.7224705 | E6: =C6/B6 -> 57.064372 | F6: =1000*D6/B6 -> 281839.56 | G6: =F6/E6 -> 4938.9761
A7: 45352 | B7: 0.020653 | C7: 1.18557 | D7: 5.9361376 | E7: =C7/B7 -> 57.404251 | F7: =1000*D7/B7 -> 287422.53 | G7: =F7/E7 -> 5006.9904
A8: 45383 | B8: 0.020605 | C8: 1.210923 | D8: 6.0440419 | E8: =C8/B8 -> 58.768406 | F8: =1000*D8/B8 -> 293328.9 | G8: =F8/E8 -> 4991.2686
A9: 45413 | B9: 0.020913 | C9: 1.243573 | D9: 6.27816 | E9: =C9/B9 -> 59.464113 | F9: =1000*D9/B9 -> 300203.7 | G9: =F9/E9 -> 5048.4853
A10: 45444 | B10: 0.020755 | C10: 1.25092 | D10: 6.3008488 | E10: =C10/B10 -> 60.270778 | F10: =1000*D10/B10 -> 303582.21 | G10: =F10/E10 -> 5036.9719
A11: 45474 | B11: 0.020828 | C11: 1.254401 | D11: 6.2957014 | E11: =C11/B11 -> 60.226666 | F11: =1000*D11/B11 -> 302271.05 | G11: =F11/E11 -> 5018.8906
A12: 45505 | B12: 0.020631 | C12: 1.258359 | D12: 6.3059404 | E12: =C12/B12 -> 60.993602 | F12: =1000*D12/B12 -> 305653.65 | G12: =F12/E12 -> 5011.2411
A13: 45536 | B13: 0.020767 | C13: 1.273711 | D13: 6.4140888 | E13: =C13/B13 -> 61.333414 | F13: =1000*D13/B13 -> 308859.67 | G13: =F13/E13 -> 5035.7489
A14: 45566 | B14: 0.020924 | C14: 1.293499 | D14: 6.534294 | E14: =C14/B14 -> 61.818916 | F14: =1000*D14/B14 -> 312287.04 | G14: =F14/E14 -> 5051.6421
A15: 45597 | B15: 0.021228 | C15: 1.27381 | D15: 6.4180118 | E15: =C15/B15 -> 60.006124 | F15: =1000*D15/B15 -> 302337.09 | G15: =F15/E15 -> 5038.4373
A16: 45627 | B16: 0.022066 | C16: 1.285652 | D16: 6.448143 | E16: =C16/B16 -> 58.263935 | F16: =1000*D16/B16 -> 292220.75 | G16: =F16/E16 -> 5015.4653
... A35: 46204 | B35: 0.025813 | C35: 1.932061 | D35: 10.082753 | E35: =C35/B35 -> 74.848371 | F35: =1000*D35/B35 -> 390607.56 | G35: =F35/E35 -> 5218.6514
A36: 46235
A37: 46266
A38: 46296
A39: 46327
A40: 46357

Sheet AC
A2: Indicador Serasa Experian de Inadimplência das Empresas - Acre
A3: Mês | B3: Empresas Inadimplentes | C3: Dívidas Negativadas | D3: Dívidas Negativadas (R$) | E3: Dívida Média (por CNPJ) | F3: Dívida Média (R$) | G3: Ticket Médio (R$)
A4: 45292 | B4: 14991 | C4: 99339 | D4: 3.518211e+08 | E4: =C4/B4 -> 6.6265759 | F4: =D4/B4 -> 23468.822 | G4: =F4/E4 -> 3541.6212
A5: 45323 | B5: 14972 | C5: 99627 | D5: 3.5707248e+08 | E5: =C5/B5 -> 6.6542212 | F5: =D5/B5 -> 23849.351 | G5: =F5/E5 -> 3584.0935
A6: 45352 | B6: 15027 | C6: 100054 | D6: 3.635906e+08 | E6: =C6/B6 -> 6.6582818 | F6: =D6/B6 -> 24195.821 | G6: =F6/E6 -> 3633.9437
A7: 45383 | B7: 15147 | C7: 101398 | D7: 3.7525932e+08 | E7: =C7/B7 -> 6.6942629 | F7: =D7/B7 -> 24774.498 | G7: =F7/E7 -> 3700.8552
A8: 45413 | B8: 15182 | C8: 102838 | D8: 3.8664379e+08 | E8: =C8/B8 -> 6.7736794 | F8: =D8/B8 -> 25467.25 | G8: =F8/E8 -> 3759.7365
A9: 45444 | B9: 15258 | C9: 103310 | D9: 3.9175474e+08 | E9: =C9/B9 -> 6.7708743 | F9: =D9/B9 -> 25675.366 | G9: =F9/E9 -> 3792.0312
A10: 45474 | B10: 15155 | C10: 103121 | D10: 3.9634025e+08 | E10: =C10/B10 -> 6.804421 | F10: =D10/B10 -> 26152.441 | G10: =F10/E10 -> 3843.4484
A11: 45505 | B11: 15129 | C11: 103886 | D11: 4.0063646e+08 | E11: =C11/B11 -> 6.8666799 | F11: =D11/B11 -> 26481.357 | G11: =F11/E11 -> 3856.5009
A12: 45536 | B12: 15084 | C12: 103983 | D12: 4.0895736e+08 | E12: =C12/B12 -> 6.8935959 | F12: =D12/B12 -> 27111.997 | G12: =F12/E12 -> 3932.9252
A13: 45566 | B13: 15192 | C13: 106151 | D13: 4.2482645e+08 | E13: =C13/B13 -> 6.9872959 | F13: =D13/B13 -> 27963.826 | G13: =F13/E13 -> 4002.0956
A14: 45597 | B14: 14292 | C14: 83678 | D14: 3.2229622e+08 | E14: =C14/B14 -> 5.8548839 | F14: =D14/B14 -> 22550.813 | G14: =F14/E14 -> 3851.6244
A15: 45627 | B15: 14108 | C15: 82429 | D15: 3.1697392e+08 | E15: =C15/B15 -> 5.8427134 | F15: =D15/B15 -> 22467.672 | G15: =F15/E15 -> 3845.4175
... A23: 45870 | B23: 16461 | C23: 96935 | D23: 398492158 | E23: =C23/B23 -> 5.8887674 | F23: =D23/B23 -> 24208.259 | G23: =F23/E23 -> 4110.9213
A24: 45901 | B24: 17006 | C24: 99348 | D24: 411272398 | E24: =IFERROR(C24/B24,"") -> 5.8419381 | F24: =IFERROR(D24/B24,"") -> 24183.958 | G24: =IFERROR(F24/E24,"") -> 4139.7149
A25: 45931 | B25: 17488 | C25: 101975 | D25: 419696910 | E25: =IFERROR(C25/B25,"") -> 5.8311414 | F25: =IFERROR(D25/B25,"") -> 23999.137 | G25: =IFERROR(F25/E25,"") -> 4115.6843
A26: 45962 | B26: 18172 | C26: 104138 | D26: 435260246 | E26: =IFERROR(C26/B26,"") -> 5.7306846 | F26: =IFERROR(D26/B26,"") -> 23952.248 | G26: =IFERROR(F26/E26,"") -> 4179.6486
A27: 45992 | B27: 18102 | C27: 104909 | D27: 440431649 | E27: =IFERROR(C27/B27,"") -> 5.795437 | F27: =IFERROR(D27/B27,"") -> 24330.552 | G27: =IFERROR(F27/E27,"") -> 4198.2256
A28: 46023 | B28: 13749 | C28: 67896 | D28: 266871455 | E28: =IFERROR(C28/B28,"") -> 4.9382501 | F28: =IFERROR(D28/B28,"") -> 19410.245 | G28: =IFERROR(F28/E28,"") -> 3930.5917
A29: 46054 | B29: 13801 | C29: 68160 | D29: 269358800 | E29: =IFERROR(C29/B29,"") -> 4.9387726 | F29: =IFERROR(D29/B29,"") -> 19517.339 | G29: =IFERROR(F29/E29,"") -> 3951.8603
A30: 46082 | B30: 13881 | C30: 69123 | D30: 276789019 | E30: =IFERROR(C30/B30,"") -> 4.9796845 | F30: =IFERROR(D30/B30,"") -> 19940.135 | G30: =IFERROR(F30/E30,"") -> 4004.297
A31: 46113 | B31: 13998 | C31: 69627 | D31: 274642765 | E31: =IFERROR(C31/B31,"") -> 4.9740677 | F31: =IFERROR(D31/B31,"") -> 19620.143 | G31: =IFERROR(F31/E31,"") -> 3944.4865
A32: 46143 | B32: 14068 | C32: 70438 | D32: 282271658 | E32: =IFERROR(C32/B32,"") -> 5.0069662 | F32: =IFERROR(D32/B32,"") -> 20064.804 | G32: =IFERROR(F32/E32,"") -> 4007.3775
A33: 46174 | B33: 14099 | C33: 70475 | D33: 283207709 | E33: =IFERROR(C33/B33,"") -> 4.9985815 | F33: =IFERROR(D33/B33,"") -> 20087.078 | G33: =IFERROR(F33/E33,"") -> 4018.5556
A34: 46204 | B34: 14057 | C34: 69841 | D34: 276075161 | E34: =IFERROR(C34/B34,"") -> 4.9684143 | F34: =IFERROR(D34/B34,"") -> 19639.693 | G34: =IFERROR(F34/E34,"") -> 3952.9096
A35: 46235
A36: 46266
A37: 46296
A38: 46327
A39: 46357

Sheet AL
A2: Indicador Serasa Experian de Inadimplência das Empresas - Alagoas
A3: Mês | B3: Empresas Inadimplentes | C3: Dívidas Negativadas | D3: Dívidas Negativadas (R$) | E3: Dívida Média (por CNPJ) | F3: Dívida Média (R$) | G3: Ticket Médio (R$)
A4: 45292 | B4: 85630 | C4: 322973 | D4: 6.897153e+08 | E4: =C4/B4 -> 3.7717272 | F4: =D4/B4 -> 8054.5989 | G4: =F4/E4 -> 2135.52
A5: 45323 | B5: 88571 | C5: 330257 | D5: 7.0705108e+08 | E5: =C5/B5 -> 3.7287261 | F5: =D5/B5 -> 7982.8734 | G5: =F5/E5 -> 2140.9117
A6: 45352 | B6: 90311 | C6: 338105 | D6: 7.3132058e+08 | E6: =C6/B6 -> 3.7437854 | F6: =D6/B6 -> 8097.8018 | G6: =F6/E6 -> 2162.9984
A7: 45383 | B7: 86574 | C7: 333331 | D7: 7.6057881e+08 | E7: =C7/B7 -> 3.8502437 | F7: =D7/B7 -> 8785.3028 | G7: =F7/E7 -> 2281.7524
A8: 45413 | B8: 86309 | C8: 336512 | D8: 7.8760937e+08 | E8: =C8/B8 -> 3.8989213 | F8: =D8/B8 -> 9125.4605 | G8: =F8/E8 -> 2340.509
A9: 45444 | B9: 86249 | C9: 332806 | D9: 7.935303e+08 | E9: =C9/B9 -> 3.858665 | F9: =D9/B9 -> 9200.458 | G9: =F9/E9 -> 2384.363
A10: 45474 | B10: 83152 | C10: 322748 | D10: 7.753503e+08 | E10: =C10/B10 -> 3.881422 | F10: =D10/B10 -> 9324.4936 | G10: =F10/E10 -> 2402.3396
A11: 45505 | B11: 78350 | C11: 311588 | D11: 7.6842143e+08 | E11: =C11/B11 -> 3.976873 | F11: =D11/B11 -> 9807.5485 | G11: =F11/E11 -> 2466.1458
A12: 45536 | B12: 78964 | C12: 314403 | D12: 7.8679888e+08 | E12: =C12/B12 -> 3.9815992 | F12: =D12/B12 -> 9964.02 | G12: =F12/E12 -> 2502.5171
A13: 45566 | B13: 79232 | C13: 317994 | D13: 8.1966676e+08 | E13: =C13/B13 -> 4.0134542 | F13: =D13/B13 -> 10345.148 | G13: =F13/E13 -> 2577.6171
A14: 45597 | B14: 78973 | C14: 308404 | D14: 7.9085757e+08 | E14: =C14/B14 -> 3.9051828 | F14: =D14/B14 -> 10014.278 | G14: =F14/E14 -> 2564.3558
A15: 45627 | B15: 78230 | C15: 303514 | D15: 7.8583427e+08 | E15: =C15/B15 -> 3.8797648 | F15: =D15/B15 -> 10045.178 | G15: =F15/E15 -> 2589.1203
... A23: 45870 | B23: 70689 | C23: 310967 | D23: 931809534 | E23: =C23/B23 -> 4.3990861 | F23: =D23/B23 -> 13181.818 | G23: =F23/E23 -> 2996.4901
A24: 45901 | B24: 75034 | C24: 321388 | D24: 953705982 | E24: =IFERROR(C24/B24,"") -> 4.2832316 | F24: =IFERROR(D24/B24,"") -> 12710.318 | G24: =IFERROR(F24/E24,"") -> 2967.4598
A25: 45931 | B25: 77875 | C25: 333827 | D25: 978809491 | E25: =IFERROR(C25/B25,"") -> 4.286703 | F25: =IFERROR(D25/B25,"") -> 12568.982 | G25: =IFERROR(F25/E25,"") -> 2932.0861
A26: 45962 | B26: 79893 | C26: 344432 | D26: 1026200042 | E26: =IFERROR(C26/B26,"") -> 4.3111662 | F26: =IFERROR(D26/B26,"") -> 12844.68 | G26: =IFERROR(F26/E26,"") -> 2979.3981
A27: 45992 | B27: 80681 | C27: 349691 | D27: 1041765583 | E27: =IFERROR(C27/B27,"") -> 4.3342423 | F27: =IFERROR(D27/B27,"") -> 12912.155 | G27: =IFERROR(F27/E27,"") -> 2979.1032
A28: 46023 | B28: 64683 | C28: 251710 | D28: 704872382 | E28: =IFERROR(C28/B28,"") -> 3.8914398 | F28: =IFERROR(D28/B28,"") -> 10897.336 | G28: =IFERROR(F28/E28,"") -> 2800.3352
A29: 46054 | B29: 65132 | C29: 254366 | D29: 716164950 | E29: =IFERROR(C29/B29,"") -> 3.9053921 | F29: =IFERROR(D29/B29,"") -> 10995.593 | G29: =IFERROR(F29/E29,"") -> 2815.4901
A30: 46082 | B30: 63380 | C30: 254282 | D30: 733726720 | E30: =IFERROR(C30/B30,"") -> 4.0120227 | F30: =IFERROR(D30/B30,"") -> 11576.629 | G30: =IFERROR(F30/E30,"") -> 2885.4843
A31: 46113 | B31: 64335 | C31: 259699 | D31: 754181961 | E31: =IFERROR(C31/B31,"") -> 4.0366674 | F31: =IFERROR(D31/B31,"") -> 11722.732 | G31: =IFERROR(F31/E31,"") -> 2904.0619
A32: 46143 | B32: 59819 | C32: 254656 | D32: 778588143 | E32: =IFERROR(C32/B32,"") -> 4.2571089 | F32: =IFERROR(D32/B32,"") -> 13015.733 | G32: =IFERROR(F32/E32,"") -> 3057.4113
A33: 46174 | B33: 60253 | C33: 256739 | D33: 790105265 | E33: =IFERROR(C33/B33,"") -> 4.261016 | F33: =IFERROR(D33/B33,"") -> 13113.127 | G33: =IFERROR(F33/E33,"") -> 3077.4649
A34: 46204 | B34: 60303 | C34: 255048 | D34: 777077657 | E34: =IFERROR(C34/B34,"") -> 4.2294413 | F34: =IFERROR(D34/B34,"") -> 12886.219 | G34: =IFERROR(F34/E34,"") -> 3046.7898
A35: 46235
A36: 46266
A37: 46296
A38: 46327
A39: 46357

Sheet AM
A2: Indicador Serasa Experian de Inadimplência das Empresas - Amazonas
A3: Mês | B3: Empresas Inadimplentes | C3: Dívidas Negativadas | D3: Dívidas Negativadas (R$) | E3: Dívida Média (por CNPJ) | F3: Dívida Média (R$) | G3: Ticket Médio (R$)
A4: 45292 | B4: 75337 | C4: 485127 | D4: 1.6063291e+09 | E4: =C4/B4 -> 6.4394255 | F4: =D4/B4 -> 21321.914 | G4: =F4/E4 -> 3311.1516
A5: 45323 | B5: 73036 | C5: 488936 | D5: 1.643605e+09 | E5: =C5/B5 -> 6.6944521 | F5: =D5/B5 -> 22504.039 | G5: =F5/E5 -> 3361.5953
A6: 45352 | B6: 73503 | C6: 495562 | D6: 1.6748063e+09 | E6: =C6/B6 -> 6.7420649 | F6: =D6/B6 -> 22785.551 | G6: =F6/E6 -> 3379.6101
A7: 45383 | B7: 77125 | C7: 508138 | D7: 1.7294921e+09 | E7: =C7/B7 -> 6.5884992 | F7: =D7/B7 -> 22424.533 | G7: =F7/E7 -> 3403.5874
A8: 45413 | B8: 79004 | C8: 520823 | D8: 1.7816037e+09 | E8: =C8/B8 -> 6.5923624 | F8: =D8/B8 -> 22550.804 | G8: =F8/E8 -> 3420.747
A9: 45444 | B9: 79490 | C9: 526561 | D9: 1.8086392e+09 | E9: =C9/B9 -> 6.624242 | F9: =D9/B9 -> 22753.041 | G9: =F9/E9 -> 3434.8142
A10: 45474 | B10: 79564 | C10: 526870 | D10: 1.8218953e+09 | E10: =C10/B10 -> 6.6219647 | F10: =D10/B10 -> 22898.488 | G10: =F10/E10 -> 3457.9599
A11: 45505 | B11: 80149 | C11: 527602 | D11: 1.8556779e+09 | E11: =C11/B11 -> 6.5827646 | F11: =D11/B11 -> 23152.852 | G11: =F11/E11 -> 3517.1928
A12: 45536 | B12: 80487 | C12: 532088 | D12: 1.901227e+09 | E12: =C12/B12 -> 6.6108564 | F12: =D12/B12 -> 23621.542 | G12: =F12/E12 -> 3573.1439
A13: 45566 | B13: 81128 | C13: 541591 | D13: 1.9698776e+09 | E13: =C13/B13 -> 6.6757593 | F13: =D13/B13 -> 24281.106 | G13: =F13/E13 -> 3637.2051
A14: 45597 | B14: 81620 | C14: 547231 | D14: 1.9864146e+09 | E14: =C14/B14 -> 6.704619 | F14: =D14/B14 -> 24337.351 | G14: =F14/E14 -> 3629.938
A15: 45627 | B15: 80576 | C15: 535017 | D15: 1.9249296e+09 | E15: =C15/B15 -> 6.6399052 | F15: =D15/B15 -> 23889.615 | G15: =F15/E15 -> 3597.8849
... A23: 45870 | B23: 130440 | C23: 724854 | D23: 2579135565 | E23: =C23/B23 -> 5.5569917 | F23: =D23/B23 -> 19772.582 | G23: =F23/E23 -> 3558.1449
A24: 45901 | B24: 134194 | C24: 724548 | D24: 2567630814 | E24: =IFERROR(C24/B24,"") -> 5.3992578 | F24: =IFERROR(D24/B24,"") -> 19133.723 | G24: =IFERROR(F24/E24,"") -> 3543.7691
A25: 45931 | B25: 138862 | C25: 738824 | D25: 2607172556 | E25: =IFERROR(C25/B25,"") -> 5.3205629 | F25: =IFERROR(D25/B25,"") -> 18775.277 | G25: =IFERROR(F25/E25,"") -> 3528.8141
A26: 45962 | B26: 141979 | C26: 752076 | D26: 2673980607 | E26: =IFERROR(C26/B26,"") -> 5.2970932 | F26: =IFERROR(D26/B26,"") -> 18833.635 | G26: =IFERROR(F26/E26,"") -> 3555.4659
A27: 45992 | B27: 142107 | C27: 753556 | D27: 2678492994 | E27: =IFERROR(C27/B27,"") -> 5.3027367 | F27: =IFERROR(D27/B27,"") -> 18848.424 | G27: =IFERROR(F27/E27,"") -> 3554.4711
A28: 46023 | B28: 143055 | C28: 763227 | D28: 2693231903 | E28: =IFERROR(C28/B28,"") -> 5.3351997 | F28: =IFERROR(D28/B28,"") -> 18826.549 | G28: =IFERROR(F28/E28,"") -> 3528.743
A29: 46054 | B29: 145613 | C29: 794390 | D29: 2739112290 | E29: =IFERROR(C29/B29,"") -> 5.4554882 | F29: =IFERROR(D29/B29,"") -> 18810.905 | G29: =IFERROR(F29/E29,"") -> 3448.07
A30: 46082 | B30: 146950 | C30: 831871 | D30: 2901482104 | E30: =IFERROR(C30/B30,"") -> 5.6609119 | F30: =IFERROR(D30/B30,"") -> 19744.689 | G30: =IFERROR(F30/E30,"") -> 3487.8991
A31: 46113 | B31: 148094 | C31: 855727 | D31: 3026400570 | E31: =IFERROR(C31/B31,"") -> 5.7782692 | F31: =IFERROR(D31/B31,"") -> 20435.673 | G31: =IFERROR(F31/E31,"") -> 3536.6426
A32: 46143 | B32: 149064 | C32: 881432 | D32: 3182209047 | E32: =IFERROR(C32/B32,"") -> 5.9131111 | F32: =IFERROR(D32/B32,"") -> 21347.938 | G32: =IFERROR(F32/E32,"") -> 3610.2717
A33: 46174 | B33: 150010 | C33: 892449 | D33: 3233689864 | E33: =IFERROR(C33/B33,"") -> 5.9492634 | F33: =IFERROR(D33/B33,"") -> 21556.495 | G33: =IFERROR(F33/E33,"") -> 3623.389
A34: 46204 | B34: 150990 | C34: 908135 | D34: 3321058493 | E34: =IFERROR(C34/B34,"") -> 6.0145374 | F34: =IFERROR(D34/B34,"") -> 21995.221 | G34: =IFERROR(F34/E34,"") -> 3657.0097
A35: 46235
A36: 46266
A37: 46296
A38: 46327
A39: 46357

Sheet AP
A2: Indicador Serasa Experian de Inadimplência das Empresas - Amapá
A3: Mês | B3: Empresas Inadimplentes | C3: Dívidas Negativadas | D3: Dívidas Negativadas (R$) | E3: Dívida Média (por CNPJ) | F3: Dívida Média (R$) | G3: Ticket Médio (R$)
A4: 45292 | B4: 15655 | C4: 91208 | D4: 2.8799126e+08 | E4: =C4/B4 -> 5.8261258 | F4: =D4/B4 -> 18396.12 | G4: =F4/E4 -> 3157.5219
A5: 45323 | B5: 15698 | C5: 91289 | D5: 2.9111291e+08 | E5: =C5/B5 -> 5.8153268 | F5: =D5/B5 -> 18544.586 | G5: =F5/E5 -> 3188.9155
A6: 45352 | B6: 15717 | C6: 91882 | D6: 2.9647874e+08 | E6: =C6/B6 -> 5.8460266 | F6: =D6/B6 -> 18863.57 | G6: =F6/E6 -> 3226.7336
A7: 45383 | B7: 15875 | C7: 92798 | D7: 3.0444458e+08 | E7: =C7/B7 -> 5.8455433 | F7: =D7/B7 -> 19177.611 | G7: =F7/E7 -> 3280.7235
A8: 45413 | B8: 15894 | C8: 93149 | D8: 3.1168039e+08 | E8: =C8/B8 -> 5.8606392 | F8: =D8/B8 -> 19609.94 | G8: =F8/E8 -> 3346.0411
A9: 45444 | B9: 15894 | C9: 93087 | D9: 3.1786165e+08 | E9: =C9/B9 -> 5.8567384 | F9: =D9/B9 -> 19998.845 | G9: =F9/E9 -> 3414.6728
A10: 45474 | B10: 15823 | C10: 93765 | D10: 3.3009414e+08 | E10: =C10/B10 -> 5.9258674 | F10: =D10/B10 -> 20861.666 | G10: =F10/E10 -> 3520.4409
A11: 45505 | B11: 15771 | C11: 94158 | D11: 3.3543457e+08 | E11: =C11/B11 -> 5.9703253 | F11: =D11/B11 -> 21269.074 | G11: =F11/E11 -> 3562.4649
A12: 45536 | B12: 15771 | C12: 93520 | D12: 3.3964527e+08 | E12: =C12/B12 -> 5.9298713 | F12: =D12/B12 -> 21536.065 | G12: =F12/E12 -> 3631.7929
A13: 45566 | B13: 15853 | C13: 94598 | D13: 3.5073505e+08 | E13: =C13/B13 -> 5.9671986 | F13: =D13/B13 -> 22124.207 | G13: =F13/E13 -> 3707.637
A14: 45597 | B14: 15575 | C14: 82088 | D14: 2.971255e+08 | E14: =C14/B14 -> 5.2704976 | F14: =D14/B14 -> 19077.078 | G14: =F14/E14 -> 3619.5972
A15: 45627 | B15: 15531 | C15: 81205 | D15: 2.9585522e+08 | E15: =C15/B15 -> 5.2285751 | F15: =D15/B15 -> 19049.335 | G15: =F15/E15 -> 3643.3129
... A23: 45870 | B23: 18084 | C23: 89999 | D23: 361483161 | E23: =C23/B23 -> 4.9767198 | F23: =D23/B23 -> 19989.115 | G23: =F23/E23 -> 4016.5242
A24: 45901 | B24: 18527 | C24: 91706 | D24: 371367861 | E24: =IFERROR(C24/B24,"") -> 4.949857 | F24: =IFERROR(D24/B24,"") -> 20044.684 | G24: =IFERROR(F24/E24,"") -> 4049.5481
A25: 45931 | B25: 20179 | C25: 96601 | D25: 387316468 | E25: =IFERROR(C25/B25,"") -> 4.7872045 | F25: =IFERROR(D25/B25,"") -> 19194.037 | G25: =IFERROR(F25/E25,"") -> 4009.4457
A26: 45962 | B26: 21704 | C26: 100916 | D26: 425711239 | E26: =IFERROR(C26/B26,"") -> 4.6496498 | F26: =IFERROR(D26/B26,"") -> 19614.414 | G26: =IFERROR(F26/E26,"") -> 4218.4712
A27: 45992 | B27: 22964 | C27: 103411 | D27: 435671072 | E27: =IFERROR(C27/B27,"") -> 4.5031789 | F27: =IFERROR(D27/B27,"") -> 18971.916 | G27: =IFERROR(F27/E27,"") -> 4213.0051
A28: 46023 | B28: 15668 | C28: 65454 | D28: 253131624 | E28: =IFERROR(C28/B28,"") -> 4.1775594 | F28: =IFERROR(D28/B28,"") -> 16155.963 | G28: =IFERROR(F28/E28,"") -> 3867.3209
A29: 46054 | B29: 15711 | C29: 65704 | D29: 255308289 | E29: =IFERROR(C29/B29,"") -> 4.1820381 | F29: =IFERROR(D29/B29,"") -> 16250.289 | G29: =IFERROR(F29/E29,"") -> 3885.7343
A30: 46082 | B30: 15756 | C30: 66104 | D30: 262524422 | E30: =IFERROR(C30/B30,"") -> 4.1954811 | F30: =IFERROR(D30/B30,"") -> 16661.87 | G30: =IFERROR(F30/E30,"") -> 3971.3848
A31: 46113 | B31: 15843 | C31: 66039 | D31: 260589556 | E31: =IFERROR(C31/B31,"") -> 4.1683393 | F31: =IFERROR(D31/B31,"") -> 16448.246 | G31: =IFERROR(F31/E31,"") -> 3945.9949
A32: 46143 | B32: 15929 | C32: 66760 | D32: 272687889 | E32: =IFERROR(C32/B32,"") -> 4.191098 | F32: =IFERROR(D32/B32,"") -> 17118.958 | G32: =IFERROR(F32/E32,"") -> 4084.5999
A33: 46174 | B33: 15974 | C33: 66436 | D33: 272737245 | E33: =IFERROR(C33/B33,"") -> 4.1590084 | F33: =IFERROR(D33/B33,"") -> 17073.823 | G33: =IFERROR(F33/E33,"") -> 4105.2629
A34: 46204 | B34: 15951 | C34: 65701 | D34: 256727390 | E34: =IFERROR(C34/B34,"") -> 4.1189267 | F34: =IFERROR(D34/B34,"") -> 16094.752 | G34: =IFERROR(F34/E34,"") -> 3907.5111
A35: 46235
A36: 46266
A37: 46296
A38: 46327
A39: 46357

Sheet BA
A2: Indicador Serasa Experian de Inadimplência das Empresas - Bahia
A3: Mês | B3: Empresas Inadimplentes | C3: Dívidas Negativadas | D3: Dívidas Negativadas (R$) | E3: Dívida Média (por CNPJ) | F3: Dívida Média (R$) | G3: Ticket Médio (R$)
A4: 45292 | B4: 312999 | C4: 1864563 | D4: 4.6643932e+09 | E4: =C4/B4 -> 5.9570893 | F4: =D4/B4 -> 14902.262 | G4: =F4/E4 -> 2501.6013
A5: 45323 | B5: 315823 | C5: 1871482 | D5: 4.7497089e+09 | E5: =C5/B5 -> 5.9257306 | F5: =D5/B5 -> 15039.148 | G5: =F5/E5 -> 2537.9399
A6: 45352 | B6: 318969 | C6: 1929363 | D6: 4.9580689e+09 | E6: =C6/B6 -> 6.0487477 | F6: =D6/B6 -> 15544.046 | G6: =F6/E6 -> 2569.7958
A7: 45383 | B7: 321254 | C7: 1939129 | D7: 5.0817613e+09 | E7: =C7/B7 -> 6.0361241 | F7: =D7/B7 -> 15818.515 | G7: =F7/E7 -> 2620.6412
A8: 45413 | B8: 321311 | C8: 1957662 | D8: 5.2402053e+09 | E8: =C8/B8 -> 6.0927326 | F8: =D8/B8 -> 16308.826 | G8: =F8/E8 -> 2676.7671
A9: 45444 | B9: 322060 | C9: 1962923 | D9: 5.3183736e+09 | E9: =C9/B9 -> 6.0948985 | F9: =D9/B9 -> 16513.611 | G9: =F9/E9 -> 2709.4153
A10: 45474 | B10: 318446 | C10: 1952574 | D10: 5.2988247e+09 | E10: =C10/B10 -> 6.1315702 | F10: =D10/B10 -> 16639.634 | G10: =F10/E10 -> 2713.7638
A11: 45505 | B11: 317292 | C11: 1960229 | D11: 5.3521316e+09 | E11: =C11/B11 -> 6.1779969 | F11: =D11/B11 -> 16868.158 | G11: =F11/E11 -> 2730.3604
A12: 45536 | B12: 321205 | C12: 1987228 | D12: 5.4887131e+09 | E12: =C12/B12 -> 6.1867904 | F12: =D12/B12 -> 17087.882 | G12: =F12/E12 -> 2761.9946
A13: 45566 | B13: 329056 | C13: 2029453 | D13: 5.6811567e+09 | E13: =C13/B13 -> 6.1675004 | F13: =D13/B13 -> 17265.015 | G13: =F13/E13 -> 2799.3537
A14: 45597 | B14: 319087 | C14: 1836545 | D14: 5.0012208e+09 | E14: =C14/B14 -> 5.7556246 | F14: =D14/B14 -> 15673.533 | G14: =F14/E14 -> 2723.1681
A15: 45627 | B15: 316175 | C15: 1823530 | D15: 4.9401115e+09 | E15: =C15/B15 -> 5.7674705 | F15: =D15/B15 -> 15624.611 | G15: =F15/E15 -> 2709.0925
... A23: 45870 | B23: 353652 | C23: 2073692 | D23: 6187255403 | E23: =C23/B23 -> 5.8636513 | F23: =D23/B23 -> 17495.321 | G23: =F23/E23 -> 2983.6906
A24: 45901 | B24: 363774 | C24: 2093848 | D24: 6230434274 | E24: =IFERROR(C24/B24,"") -> 5.7559034 | F24: =IFERROR(D24/B24,"") -> 17127.212 | G24: =IFERROR(F24/E24,"") -> 2975.5905
A25: 45931 | B25: 375330 | C25: 2132194 | D25: 6314190084 | E25: =IFERROR(C25/B25,"") -> 5.6808515 | F25: =IFERROR(D25/B25,"") -> 16823.036 | G25: =IFERROR(F25/E25,"") -> 2961.3582
A26: 45962 | B26: 383297 | C26: 2161473 | D26: 6519612980 | E26: =IFERROR(C26/B26,"") -> 5.6391597 | F26: =IFERROR(D26/B26,"") -> 17009.298 | G26: =IFERROR(F26/E26,"") -> 3016.2824
A27: 45992 | B27: 386175 | C27: 2184965 | D27: 6575624932 | E27: =IFERROR(C27/B27,"") -> 5.6579659 | F27: =IFERROR(D27/B27,"") -> 17027.578 | G27: =IFERROR(F27/E27,"") -> 3009.4875
A28: 46023 | B28: 321980 | C28: 1612287 | D28: 4177816225 | E28: =IFERROR(C28/B28,"") -> 5.0074135 | F28: =IFERROR(D28/B28,"") -> 12975.39 | G28: =IFERROR(F28/E28,"") -> 2591.2361
A29: 46054 | B29: 324175 | C29: 1628643 | D29: 4233371804 | E29: =IFERROR(C29/B29,"") -> 5.0239624 | F29: =IFERROR(D29/B29,"") -> 13058.909 | G29: =IFERROR(F29/E29,"") -> 2599.3246
A30: 46082 | B30: 324660 | C30: 1656696 | D30: 4354508255 | E30: =IFERROR(C30/B30,"") -> 5.1028645 | F30: =IFERROR(D30/B30,"") -> 13412.518 | G30: =IFERROR(F30/E30,"") -> 2628.4293
A31: 46113 | B31: 326255 | C31: 1681192 | D31: 4461402086 | E31: =IFERROR(C31/B31,"") -> 5.153 | F31: =IFERROR(D31/B31,"") -> 13674.586 | G31: =IFERROR(F31/E31,"") -> 2653.7136
A32: 46143 | B32: 328055 | C32: 1706982 | D32: 4575100043 | E32: =IFERROR(C32/B32,"") -> 5.2033409 | F32: =IFERROR(D32/B32,"") -> 13946.137 | G32: =IFERROR(F32/E32,"") -> 2680.2275
A33: 46174 | B33: 332416 | C33: 1724713 | D33: 4638588551 | E33: =IFERROR(C33/B33,"") -> 5.1884175 | F33: =IFERROR(D33/B33,"") -> 13954.168 | G33: =IFERROR(F33/E33,"") -> 2689.4843
A34: 46204 | B34: 333520 | C34: 1730338 | D34: 4674399111 | E34: =IFERROR(C34/B34,"") -> 5.1881087 | F34: =IFERROR(D34/B34,"") -> 14015.349 | G34: =IFERROR(F34/E34,"") -> 2701.437
A35: 46235
A36: 46266
A37: 46296
A38: 46327
A39: 46357

Sheet CE
A2: Indicador Serasa Experian de Inadimplência das Empresas - Ceará
A3: Mês | B3: Empresas Inadimplentes | C3: Dívidas Negativadas | D3: Dívidas Negativadas (R$) | E3: Dívida Média (por CNPJ) | F3: Dívida Média (R$) | G3: Ticket Médio (R$)
A4: 45292 | B4: 160119 | C4: 1034979 | D4: 2.8912606e+09 | E4: =C4/B4 -> 6.4638113 | F4: =D4/B4 -> 18056.949 | G4: =F4/E4 -> 2793.5452
A5: 45323 | B5: 159381 | C5: 1012688 | D5: 2.80133e+09 | E5: =C5/B5 -> 6.3538816 | F5: =D5/B5 -> 17576.311 | G5: =F5/E5 -> 2766.232
A6: 45352 | B6: 162306 | C6: 1044849 | D6: 2.9242756e+09 | E6: =C6/B6 -> 6.4375254 | F6: =D6/B6 -> 18017.051 | G6: =F6/E6 -> 2798.7542
A7: 45383 | B7: 162917 | C7: 1060920 | D7: 2.9980967e+09 | E7: =C7/B7 -> 6.5120276 | F7: =D7/B7 -> 18402.602 | G7: =F7/E7 -> 2825.9404
A8: 45413 | B8: 163098 | C8: 1086864 | D8: 3.1468955e+09 | E8: =C8/B8 -> 6.6638708 | F8: =D8/B8 -> 19294.507 | G8: =F8/E8 -> 2895.3903
A9: 45444 | B9: 163694 | C9: 1096529 | D9: 3.1976645e+09 | E9: =C9/B9 -> 6.6986511 | F9: =D9/B9 -> 19534.403 | G9: =F9/E9 -> 2916.1696
A10: 45474 | B10: 161931 | C10: 1089511 | D10: 3.1691901e+09 | E10: =C10/B10 -> 6.7282423 | F10: =D10/B10 -> 19571.238 | G10: =F10/E10 -> 2908.8188
A11: 45505 | B11: 160803 | C11: 1069518 | D11: 3.163703e+09 | E11: =C11/B11 -> 6.6511073 | F11: =D11/B11 -> 19674.403 | G11: =F11/E11 -> 2958.0643
A12: 45536 | B12: 161855 | C12: 1081378 | D12: 3.2082633e+09 | E12: =C12/B12 -> 6.6811529 | F12: =D12/B12 -> 19821.836 | G12: =F12/E12 -> 2966.8287
A13: 45566 | B13: 163798 | C13: 1127051 | D13: 3.3677795e+09 | E13: =C13/B13 -> 6.8807372 | F13: =D13/B13 -> 20560.565 | G13: =F13/E13 -> 2988.134
A14: 45597 | B14: 163189 | C14: 1056033 | D14: 3.1184908e+09 | E14: =C14/B14 -> 6.4712266 | F14: =D14/B14 -> 19109.688 | G14: =F14/E14 -> 2953.024
A15: 45627 | B15: 163719 | C15: 1065511 | D15: 3.0870035e+09 | E15: =C15/B15 -> 6.5081695 | F15: =D15/B15 -> 18855.499 | G15: =F15/E15 -> 2897.2047
... A23: 45870 | B23: 191488 | C23: 1254901 | D23: 3902053035 | E23: =C23/B23 -> 6.5534185 | F23: =D23/B23 -> 20377.533 | G23: =F23/E23 -> 3109.4509
A24: 45901 | B24: 198211 | C24: 1274358 | D24: 3957600165 | E24: =IFERROR(C24/B24,"") -> 6.4293001 | F24: =IFERROR(D24/B24,"") -> 19966.602 | G24: =IFERROR(F24/E24,"") -> 3105.5639
A25: 45931 | B25: 204815 | C25: 1291230 | D25: 4011148401 | E25: =IFERROR(C25/B25,"") -> 6.3043722 | F25: =IFERROR(D25/B25,"") -> 19584.251 | G25: =IFERROR(F25/E25,"") -> 3106.4554
A26: 45962 | B26: 209126 | C26: 1302431 | D26: 4174605889 | E26: =IFERROR(C26/B26,"") -> 6.2279726 | F26: =IFERROR(D26/B26,"") -> 19962.156 | G26: =IFERROR(F26/E26,"") -> 3205.2415
A27: 45992 | B27: 212270 | C27: 1316129 | D27: 4203182313 | E27: =IFERROR(C27/B27,"") -> 6.2002591 | F27: =IFERROR(D27/B27,"") -> 19801.113 | G27: =IFERROR(F27/E27,"") -> 3193.5945
A28: 46023 | B28: 184599 | C28: 927227 | D28: 2767911416 | E28: =IFERROR(C28/B28,"") -> 5.0229254 | F28: =IFERROR(D28/B28,"") -> 14994.184 | G28: =IFERROR(F28/E28,"") -> 2985.1497
A29: 46054 | B29: 185396 | C29: 927400 | D29: 2753678383 | E29: =IFERROR(C29/B29,"") -> 5.0022654 | F29: =IFERROR(D29/B29,"") -> 14852.955 | G29: =IFERROR(F29/E29,"") -> 2969.2456
A30: 46082 | B30: 188390 | C30: 954816 | D30: 2866084785 | E30: =IFERROR(C30/B30,"") -> 5.0682945 | F30: =IFERROR(D30/B30,"") -> 15213.572 | G30: =IFERROR(F30/E30,"") -> 3001.7142
A31: 46113 | B31: 190849 | C31: 974637 | D31: 2948695567 | E31: =IFERROR(C31/B31,"") -> 5.1068489 | F31: =IFERROR(D31/B31,"") -> 15450.411 | G31: =IFERROR(F31/E31,"") -> 3025.4295
A32: 46143 | B32: 191840 | C32: 997709 | D32: 3096629717 | E32: =IFERROR(C32/B32,"") -> 5.200735 | F32: =IFERROR(D32/B32,"") -> 16141.731 | G32: =IFERROR(F32/E32,"") -> 3103.7404
A33: 46174 | B33: 193396 | C33: 1005754 | D33: 3128115534 | E33: =IFERROR(C33/B33,"") -> 5.2004902 | F33: =IFERROR(D33/B33,"") -> 16174.665 | G33: =IFERROR(F33/E33,"") -> 3110.2193
A34: 46204 | B34: 193822 | C34: 1002804 | D34: 3056996659 | E34: =IFERROR(C34/B34,"") -> 5.1738399 | F34: =IFERROR(D34/B34,"") -> 15772.186 | G34: =IFERROR(F34/E34,"") -> 3048.4488
A35: 46235
A36: 46266
A37: 46296
A38: 46327
A39: 46357

Sheet DF
A2: Indicador Serasa Experian de Inadimplência das Empresas - Distrito Federal
A3: Mês | B3: Empresas Inadimplentes | C3: Dívidas Negativadas | D3: Dívidas Negativadas (R$) | E3: Dívida Média (por CNPJ) | F3: Dívida Média (R$) | G3: Ticket Médio (R$)
A4: 45292 | B4: 129614 | C4: 1131883 | D4: 3.4105196e+09 | E4: =C4/B4 -> 8.7327218 | F4: =D4/B4 -> 26312.895 | G4: =F4/E4 -> 3013.138
A5: 45323 | B5: 130240 | C5: 1135664 | D5: 3.4420352e+09 | E5: =C5/B5 -> 8.7197789 | F5: =D5/B5 -> 26428.403 | G5: =F5/E5 -> 3030.857
A6: 45352 | B6: 134514 | C6: 1152520 | D6: 3.5036024e+09 | E6: =C6/B6 -> 8.5680301 | F6: =D6/B6 -> 26046.377 | G6: =F6/E6 -> 3039.9493
A7: 45383 | B7: 137463 | C7: 1187640 | D7: 3.6982962e+09 | E7: =C7/B7 -> 8.6397067 | F7: =D7/B7 -> 26903.939 | G7: =F7/E7 -> 3113.9876
A8: 45413 | B8: 141655 | C8: 1231844 | D8: 3.914954e+09 | E8: =C8/B8 -> 8.6960856 | F8: =D8/B8 -> 27637.246 | G8: =F8/E8 -> 3178.1249
A9: 45444 | B9: 143504 | C9: 1259496 | D9: 4.0390735e+09 | E9: =C9/B9 -> 8.776731 | F9: =D9/B9 -> 28146.069 | G9: =F9/E9 -> 3206.8966
A10: 45474 | B10: 144923 | C10: 1275083 | D10: 4.0246768e+09 | E10: =C10/B10 -> 8.7983481 | F10: =D10/B10 -> 27771.139 | G10: =F10/E10 -> 3156.4038
A11: 45505 | B11: 146104 | C11: 1292804 | D11: 4.1076784e+09 | E11: =C11/B11 -> 8.8485189 | F11: =D11/B11 -> 28114.757 | G11: =F11/E11 -> 3177.3404
A12: 45536 | B12: 147901 | C12: 1310188 | D12: 4.1730409e+09 | E12: =C12/B12 -> 8.8585473 | F12: =D12/B12 -> 28215.096 | G12: =F12/E12 -> 3185.0703
A13: 45566 | B13: 151305 | C13: 1354606 | D13: 4.3246933e+09 | E13: =C13/B13 -> 8.9528172 | F13: =D13/B13 -> 28582.62 | G13: =F13/E13 -> 3192.5839
A14: 45597 | B14: 152125 | C14: 1355438 | D14: 4.3596127e+09 | E14: =C14/B14 -> 8.9100279 | F14: =D14/B14 -> 28658.095 | G14: =F14/E14 -> 3216.3867
A15: 45627 | B15: 151227 | C15: 1354429 | D15: 4.2431322e+09 | E15: =C15/B15 -> 8.9562644 | F15: =D15/B15 -> 28058.033 | G15: =F15/E15 -> 3132.7831
... A23: 45870 | B23: 183940 | C23: 1645573 | D23: 5497823925 | E23: =C23/B23 -> 8.9462488 | F23: =D23/B23 -> 29889.224 | G23: =F23/E23 -> 3340.9784
A24: 45901 | B24: 190160 | C24: 1676749 | D24: 5549402165 | E24: =IFERROR(C24/B24,"") -> 8.8175694 | F24: =IFERROR(D24/B24,"") -> 29182.805 | G24: =IFERROR(F24/E24,"") -> 3309.6201
A25: 45931 | B25: 197750 | C25: 1697340 | D25: 5618328703 | E25: =IFERROR(C25/B25,"") -> 8.5832617 | F25: =IFERROR(D25/B25,"") -> 28411.27 | G25: =IFERROR(F25/E25,"") -> 3310.0785
A26: 45962 | B26: 203002 | C26: 1723057 | D26: 5796345939 | E26: =IFERROR(C26/B26,"") -> 8.4878819 | F26: =IFERROR(D26/B26,"") -> 28553.147 | G26: =IFERROR(F26/E26,"") -> 3363.9897
A27: 45992 | B27: 205907 | C27: 1747355 | D27: 5841747014 | E27: =IFERROR(C27/B27,"") -> 8.4861369 | F27: =IFERROR(D27/B27,"") -> 28370.803 | G27: =IFERROR(F27/E27,"") -> 3343.1942
A28: 46023 | B28: 216504 | C28: 1747837 | D28: 5879045935 | E28: =IFERROR(C28/B28,"") -> 8.073001 | F28: =IFERROR(D28/B28,"") -> 27154.445 | G28: =IFERROR(F28/E28,"") -> 3363.6122
A29: 46054 | B29: 218063 | C29: 1747451 | D29: 5898851034 | E29: =IFERROR(C29/B29,"") -> 8.0135144 | F29: =IFERROR(D29/B29,"") -> 27051.132 | G29: =IFERROR(F29/E29,"") -> 3375.689
A30: 46082 | B30: 219446 | C30: 1782989 | D30: 6165791639 | E30: =IFERROR(C30/B30,"") -> 8.1249556 | F30: =IFERROR(D30/B30,"") -> 28097.079 | G30: =IFERROR(F30/E30,"") -> 3458.121
A31: 46113 | B31: 220881 | C31: 1812485 | D31: 6337072212 | E31: =IFERROR(C31/B31,"") -> 8.2057081 | F31: =IFERROR(D31/B31,"") -> 28689.983 | G31: =IFERROR(F31/E31,"") -> 3496.3446
A32: 46143 | B32: 222865 | C32: 1863314 | D32: 6613250908 | E32: =IFERROR(C32/B32,"") -> 8.3607296 | F32: =IFERROR(D32/B32,"") -> 29673.798 | G32: =IFERROR(F32/E32,"") -> 3549.1876
A33: 46174 | B33: 225060 | C33: 1881269 | D33: 6670459935 | E33: =IFERROR(C33/B33,"") -> 8.3589665 | F33: =IFERROR(D33/B33,"") -> 29638.585 | G33: =IFERROR(F33/E33,"") -> 3545.7236
A34: 46204 | B34: 226296 | C34: 1897904 | D34: 6773232132 | E34: =IFERROR(C34/B34,"") -> 8.3868208 | F34: =IFERROR(D34/B34,"") -> 29930.852 | G34: =IFERROR(F34/E34,"") -> 3568.796
A35: 46235
A36: 46266
A37: 46296
A38: 46327
A39: 46357

Sheet ES
A2: Indicador Serasa Experian de Inadimplência das Empresas - Espírito Santo
A3: Mês | B3: Empresas Inadimplentes | C3: Dívidas Negativadas | D3: Dívidas Negativadas (R$) | E3: Dívida Média (por CNPJ) | F3: Dívida Média (R$) | G3: Ticket Médio (R$)
A4: 45292 | B4: 120912 | C4: 695063 | D4: 1.644866e+09 | E4: =C4/B4 -> 5.748503 | F4: =D4/B4 -> 13603.827 | G4: =F4/E4 -> 2366.4991
A5: 45323 | B5: 122476 | C5: 701152 | D5: 1.6755454e+09 | E5: =C5/B5 -> 5.7248114 | F5: =D5/B5 -> 13680.602 | G5: =F5/E5 -> 2389.7035
A6: 45352 | B6: 123835 | C6: 714875 | D6: 1.7275534e+09 | E6: =C6/B6 -> 5.7728025 | F6: =D6/B6 -> 13950.445 | G6: =F6/E6 -> 2416.5811
A7: 45383 | B7: 127293 | C7: 749056 | D7: 1.7881895e+09 | E7: =C7/B7 -> 5.8845027 | F7: =D7/B7 -> 14047.822 | G7: =F7/E7 -> 2387.2574
A8: 45413 | B8: 126009 | C8: 745783 | D8: 1.813935e+09 | E8: =C8/B8 -> 5.9184899 | F8: =D8/B8 -> 14395.282 | G8: =F8/E8 -> 2432.2558
A9: 45444 | B9: 127206 | C9: 748909 | D9: 1.8298484e+09 | E9: =C9/B9 -> 5.8873717 | F9: =D9/B9 -> 14384.922 | G9: =F9/E9 -> 2443.3522
A10: 45474 | B10: 126057 | C10: 740164 | D10: 1.807389e+09 | E10: =C10/B10 -> 5.8716612 | F10: =D10/B10 -> 14337.871 | G10: =F10/E10 -> 2441.8764
A11: 45505 | B11: 125680 | C11: 739912 | D11: 1.8251274e+09 | E11: =C11/B11 -> 5.8872693 | F11: =D11/B11 -> 14522.019 | G11: =F11/E11 -> 2466.6817
A12: 45536 | B12: 127012 | C12: 740010 | D12: 1.8452738e+09 | E12: =C12/B12 -> 5.8262999 | F12: =D12/B12 -> 14528.342 | G12: =F12/E12 -> 2493.5795
A13: 45566 | B13: 128070 | C13: 745427 | D13: 1.9027228e+09 | E13: =C13/B13 -> 5.8204654 | F13: =D13/B13 -> 14856.897 | G13: =F13/E13 -> 2552.5274
A14: 45597 | B14: 127781 | C14: 738942 | D14: 1.8715536e+09 | E14: =C14/B14 -> 5.7828785 | F14: =D14/B14 -> 14646.572 | G14: =F14/E14 -> 2532.7476
A15: 45627 | B15: 124171 | C15: 680066 | D15: 1.6701532e+09 | E15: =C15/B15 -> 5.4768505 | F15: =D15/B15 -> 13450.429 | G15: =F15/E15 -> 2455.8693
... A23: 45870 | B23: 134830 | C23: 747425 | D23: 1986132013 | E23: =C23/B23 -> 5.5434621 | F23: =D23/B23 -> 14730.639 | G23: =F23/E23 -> 2657.2994
A24: 45901 | B24: 136570 | C24: 749888 | D24: 1997471381 | E24: =IFERROR(C24/B24,"") -> 5.4908692 | F24: =IFERROR(D24/B24,"") -> 14625.989 | G24: =IFERROR(F24/E24,"") -> 2663.693
A25: 45931 | B25: 139809 | C25: 758906 | D25: 2021342705 | E25: =IFERROR(C25/B25,"") -> 5.4281627 | F25: =IFERROR(D25/B25,"") -> 14457.887 | G25: =IFERROR(F25/E25,"") -> 2663.4955
A26: 45962 | B26: 140431 | C26: 763231 | D26: 2068445648 | E26: =IFERROR(C26/B26,"") -> 5.4349182 | F26: =IFERROR(D26/B26,"") -> 14729.267 | G26: =IFERROR(F26/E26,"") -> 2710.1174
A27: 45992 | B27: 140626 | C27: 763821 | D27: 2077585681 | E27: =IFERROR(C27/B27,"") -> 5.4315774 | F27: =IFERROR(D27/B27,"") -> 14773.838 | G27: =IFERROR(F27/E27,"") -> 2719.9903
A28: 46023 | B28: 131641 | C28: 643375 | D28: 1573645740 | E28: =IFERROR(C28/B28,"") -> 4.8873451 | F28: =IFERROR(D28/B28,"") -> 11954.07 | G28: =IFERROR(F28/E28,"") -> 2445.923
A29: 46054 | B29: 131958 | C29: 645798 | D29: 1594039640 | E29: =IFERROR(C29/B29,"") -> 4.8939663 | F29: =IFERROR(D29/B29,"") -> 12079.901 | G29: =IFERROR(F29/E29,"") -> 2468.3255
A30: 46082 | B30: 132632 | C30: 654128 | D30: 1648160218 | E30: =IFERROR(C30/B30,"") -> 4.9319018 | F30: =IFERROR(D30/B30,"") -> 12426.565 | G30: =IFERROR(F30/E30,"") -> 2519.6295
A31: 46113 | B31: 133963 | C31: 663444 | D31: 1696042279 | E31: =IFERROR(C31/B31,"") -> 4.9524421 | F31: =IFERROR(D31/B31,"") -> 12660.528 | G31: =IFERROR(F31/E31,"") -> 2556.4212
A32: 46143 | B32: 133895 | C32: 670105 | D32: 1763108249 | E32: =IFERROR(C32/B32,"") -> 5.0047052 | F32: =IFERROR(D32/B32,"") -> 13167.842 | G32: =IFERROR(F32/E32,"") -> 2631.0925
A33: 46174 | B33: 136167 | C33: 675428 | D33: 1767422574 | E33: =IFERROR(C33/B33,"") -> 4.9602914 | F33: =IFERROR(D33/B33,"") -> 12979.816 | G33: =IFERROR(F33/E33,"") -> 2616.7446
A34: 46204 | B34: 136869 | C34: 676500 | D34: 1767810412 | E34: =IFERROR(C34/B34,"") -> 4.9426824 | F34: =IFERROR(D34/B34,"") -> 12916.076 | G34: =IFERROR(F34/E34,"") -> 2613.1713
A35: 46235
A36: 46266
A37: 46296
A38: 46327
A39: 46357

Sheet GO
A2: Indicador Serasa Experian de Inadimplência das Empresas - Goiás
A3: Mês | B3: Empresas Inadimplentes | C3: Dívidas Negativadas | D3: Dívidas Negativadas (R$) | E3: Dívida Média (por CNPJ) | F3: Dívida Média (R$) | G3: Ticket Médio (R$)
A4: 45292 | B4: 225205 | C4: 1790298 | D4: 5.062209e+09 | E4: =C4/B4 -> 7.949637 | F4: =D4/B4 -> 22478.226 | G4: =F4/E4 -> 2827.579
A5: 45323 | B5: 224568 | C5: 1800784 | D5: 5.1509399e+09 | E5: =C5/B5 -> 8.0188807 | F5: =D5/B5 -> 22937.105 | G5: =F5/E5 -> 2860.3874
A6: 45352 | B6: 213587 | C6: 1649575 | D6: 4.7120973e+09 | E6: =C6/B6 -> 7.7231994 | F6: =D6/B6 -> 22061.723 | G6: =F6/E6 -> 2856.5523
A7: 45383 | B7: 214948 | C7: 1671463 | D7: 4.8430597e+09 | E7: =C7/B7 -> 7.7761272 | F7: =D7/B7 -> 22531.308 | G7: =F7/E7 -> 2897.4974
A8: 45413 | B8: 214763 | C8: 1699549 | D8: 5.010234e+09 | E8: =C8/B8 -> 7.9136024 | F8: =D8/B8 -> 23329.13 | G8: =F8/E8 -> 2947.9785
A9: 45444 | B9: 207017 | C9: 1558030 | D9: 4.4514432e+09 | E9: =C9/B9 -> 7.5260969 | F9: =D9/B9 -> 21502.791 | G9: =F9/E9 -> 2857.0972
A10: 45474 | B10: 206984 | C10: 1542147 | D10: 4.363633e+09 | E10: =C10/B10 -> 7.4505614 | F10: =D10/B10 -> 21081.982 | G10: =F10/E10 -> 2829.5831
A11: 45505 | B11: 206608 | C11: 1539421 | D11: 4.3681752e+09 | E11: =C11/B11 -> 7.4509264 | F11: =D11/B11 -> 21142.333 | G11: =F11/E11 -> 2837.5443
A12: 45536 | B12: 207975 | C12: 1548829 | D12: 4.4288403e+09 | E12: =C12/B12 -> 7.4471884 | F12: =D12/B12 -> 21295.061 | G12: =F12/E12 -> 2859.4766
A13: 45566 | B13: 209852 | C13: 1572546 | D13: 4.5798898e+09 | E13: =C13/B13 -> 7.4935955 | F13: =D13/B13 -> 21824.38 | G13: =F13/E13 -> 2912.4043
A14: 45597 | B14: 207558 | C14: 1511174 | D14: 4.375319e+09 | E14: =C14/B14 -> 7.2807312 | F14: =D14/B14 -> 21079.982 | G14: =F14/E14 -> 2895.3112
A15: 45627 | B15: 221331 | C15: 1566250 | D15: 4.4256381e+09 | E15: =C15/B15 -> 7.0765053 | F15: =D15/B15 -> 19995.564 | G15: =F15/E15 -> 2825.6269
... A23: 45870 | B23: 258726 | C23: 1889732 | D23: 5964726471 | E23: =C23/B23 -> 7.3039895 | F23: =D23/B23 -> 23054.221 | G23: =F23/E23 -> 3156.3875
A24: 45901 | B24: 265076 | C24: 1913048 | D24: 6036014715 | E24: =IFERROR(C24/B24,"") -> 7.2169793 | F24: =IFERROR(D24/B24,"") -> 22770.884 | G24: =IFERROR(F24/E24,"") -> 3155.1821
A25: 45931 | B25: 274228 | C25: 1937523 | D25: 6081136378 | E25: =IFERROR(C25/B25,"") -> 7.0653726 | F25: =IFERROR(D25/B25,"") -> 22175.476 | G25: =IFERROR(F25/E25,"") -> 3138.6138
A26: 45962 | B26: 280493 | C26: 1969825 | D26: 6322019134 | E26: =IFERROR(C26/B26,"") -> 7.0227243 | F26: =IFERROR(D26/B26,"") -> 22538.955 | G26: =IFERROR(F26/E26,"") -> 3209.4319
A27: 45992 | B27: 284141 | C27: 1996568 | D27: 6420638715 | E27: =IFERROR(C27/B27,"") -> 7.0266804 | F27: =IFERROR(D27/B27,"") -> 22596.664 | G27: =IFERROR(F27/E27,"") -> 3215.8377
A28: 46023 | B28: 237317 | C28: 1353792 | D28: 3812795215 | E28: =IFERROR(C28/B28,"") -> 5.7045724 | F28: =IFERROR(D28/B28,"") -> 16066.254 | G28: =IFERROR(F28/E28,"") -> 2816.3818
A29: 46054 | B29: 239183 | C29: 1363064 | D29: 3854242308 | E29: =IFERROR(C29/B29,"") -> 5.6988331 | F29: =IFERROR(D29/B29,"") -> 16114.198 | G29: =IFERROR(F29/E29,"") -> 2827.6312
A30: 46082 | B30: 241732 | C30: 1395947 | D30: 4033857443 | E30: =IFERROR(C30/B30,"") -> 5.7747712 | F30: =IFERROR(D30/B30,"") -> 16687.313 | G30: =IFERROR(F30/E30,"") -> 2889.6924
A31: 46113 | B31: 244254 | C31: 1421489 | D31: 4128027256 | E31: =IFERROR(C31/B31,"") -> 5.8197164 | F31: =IFERROR(D31/B31,"") -> 16900.551 | G31: =IFERROR(F31/E31,"") -> 2904.0163
A32: 46143 | B32: 247336 | C32: 1457409 | D32: 4327324995 | E32: =IFERROR(C32/B32,"") -> 5.8924257 | F32: =IFERROR(D32/B32,"") -> 17495.735 | G32: =IFERROR(F32/E32,"") -> 2969.1905
A33: 46174 | B33: 250101 | C33: 1472763 | D33: 4399930316 | E33: =IFERROR(C33/B33,"") -> 5.888673 | F33: =IFERROR(D33/B33,"") -> 17592.614 | G33: =IFERROR(F33/E33,"") -> 2987.5345
A34: 46204 | B34: 252054 | C34: 1479808 | D34: 4375484090 | E34: =IFERROR(C34/B34,"") -> 5.8709959 | F34: =IFERROR(D34/B34,"") -> 17359.312 | G34: =IFERROR(F34/E34,"") -> 2956.7918
A35: 46235
A36: 46266
A37: 46296
A38: 46327
A39: 46357

Sheet MA
A2: Indicador Serasa Experian de Inadimplência das Empresas - Maranhão
A3: Mês | B3: Empresas Inadimplentes | C3: Dívidas Negativadas | D3: Dívidas Negativadas (R$) | E3: Dívida Média (por CNPJ) | F3: Dívida Média (R$) | G3: Ticket Médio (R$)
A4: 45292 | B4: 117496 | C4: 801370 | D4: 1.8776935e+09 | E4: =C4/B4 -> 6.8204024 | F4: =D4/B4 -> 15980.915 | G4: =F4/E4 -> 2343.1044
A5: 45323 | B5: 117486 | C5: 798933 | D5: 1.8996132e+09 | E5: =C5/B5 -> 6.80024 | F5: =D5/B5 -> 16168.847 | G5: =F5/E5 -> 2377.6877
A6: 45352 | B6: 118115 | C6: 816694 | D6: 1.9741369e+09 | E6: =C6/B6 -> 6.914397 | F6: =D6/B6 -> 16713.685 | G6: =F6/E6 -> 2417.2296
