Workbook

Sheet Geral
A2: Indicador Serasa Experian de Inadimplência das Micro e Pequenas Empresas
B3: Setor | F3: Região | K3: TOTAL
A4: Mês | B4: Comércio | C4: Serviço | D4: Indústria | E4: Demais | F4: Norte | G4: Nordeste | H4: Centro-Oeste | I4: Sudeste | J4: Sul
A5: 45292 | B5: 2388392 | C5: 3320892 | D5: 482397 | E5: 95349 | F5: 341923 | G5: 1046825 | H5: 549355 | I5: 3311847 | J5: 1037080 | K5: =SUM(F5:J5) -> 6287030
A6: 45323 | B6: 2375366 | C6: 3319593 | D6: 480555 | E6: 95656 | F6: 340722 | G6: 1053579 | H6: 550543 | I6: 3289120 | J6: 1037206 | K6: 6271170
A7: 45352 | B7: 2376730 | C7: 3338030 | D7: 482106 | E7: 96049 | F7: 343096 | G7: 1062696 | H7: 544506 | I7: 3295260 | J7: 1047357 | K7: 6292915
A8: 45383 | B8: 2388893 | C8: 3388129 | D8: 484733 | E8: 96599 | F8: 349685 | G8: 1064233 | H8: 567293 | I8: 3324545 | J8: 1052598 | K8: 6358354
A9: 45413 | B9: 2428770 | C9: 3467875 | D9: 489098 | E9: 97362 | F9: 353985 | G9: 1067442 | H9: 572625 | I9: 3443214 | J9: 1045839 | K9: 6483105
A10: 45444 | B10: 2433732 | C10: 3503945 | D10: 490586 | E10: 100071 | F10: 355459 | G10: 1068767 | H10: 567509 | I10: 3497256 | J10: 1039343 | K10: 6528334
A11: 45474 | B11: 2423269 | C11: 3504566 | D11: 488788 | E11: 100374 | F11: 355372 | G11: 1060702 | H11: 570619 | I11: 3485167 | J11: 1045137 | K11: 6516997
A12: 45505 | B12: 2412154 | C12: 3494470 | D12: 485656 | E12: 100475 | F12: 356909 | G12: 1056093 | H12: 572335 | I12: 3464935 | J12: 1042483 | K12: 6492755
A13: 45536 | B13: 2419188 | C13: 3516566 | D13: 486789 | E13: 100722 | F13: 357781 | G13: 1061357 | H13: 576806 | I13: 3480138 | J13: 1047183 | K13: 6523265
A14: 45566 | B14: 2431347 | C14: 3556771 | D14: 489557 | E14: 101276 | F14: 361397 | G14: 1072898 | H14: 584601 | I14: 3509095 | J14: 1050960 | K14: 6578951
A15: 45597 | B15: 2437811 | C15: 3475719 | D15: 539324 | E15: 120781 | F15: 362565 | G15: 1049925 | H15: 581885 | I15: 3535529 | J15: 1043731 | K15: 6573635
A16: 45627 | B16: 2426600 | C16: 3473544 | D16: 536592 | E16: 121732 | F16: 358283 | G16: 1041433 | H16: 593429 | I16: 3525766 | J16: 1039557 | K16: 6558468
A17: 45658 | B17: 2450557 | C17: 3540915 | D17: 545728 | E17: 123365 | F17: 368095 | G17: 1062051 | H17: 575459 | I17: 3599226 | J17: 1055734 | K17: 6660565
... A24: 45870 | B24: 2680723 | C24: 4240086 | D24: 630624 | E24: 144084 | F24: 457405 | G24: 1181253 | H24: 675746 | I24: 4124207 | J24: 1256906 | K24: 7695517
A25: 45901 | B25: 2743362 | C25: 4411704 | D25: 653387 | E25: 148754 | F25: 475220 | G25: 1218494 | H25: 696994 | I25: 4262531 | J25: 1303968 | K25: =SUM(F25:J25) -> 7957207
A26: 45931 | B26: 2814053 | C26: 4580520 | D26: 676108 | E26: 153972 | F26: 492330 | G26: 1260364 | H26: 722326 | I26: 4398916 | J26: 1350717 | K26: =SUM(F26:J26) -> 8224653
A27: 45962 | B27: 2857275 | C27: 4717410 | D27: 695321 | E27: 158316 | F27: 506190 | G27: 1289457 | H27: 740901 | I27: 4508796 | J27: 1382978 | K27: 8428322
A28: 45992 | B28: 2881868 | C28: 4760772 | D28: 702154 | E28: 160504 | F28: 510034 | G28: 1298648 | H28: 750538 | I28: 4550150 | J28: 1395928 | K28: 8505298
A29: 46023 | B29: 2809102 | C29: 4644087 | D29: 682820 | E29: 157435 | F29: 469041 | G29: 1105551 | H29: 719473 | I29: 4584973 | J29: 1414406 | K29: 8293444
A30: 46054 | B30: 2827433 | C30: 4709793 | D30: 690530 | E30: 159574 | F30: 473643 | G30: 1113376 | H30: 730622 | I30: 4634493 | J30: 1435196 | K30: 8387330
A31: 46082 | B31: 2835736 | C31: 4750124 | D31: 695411 | E31: 161387 | F31: 479222 | G31: 1117497 | H31: 736738 | I31: 4658468 | J31: 1450733 | K31: 8442658
A32: 46113 | B32: 2857320 | C32: 4801153 | D32: 701244 | E32: 163592 | F32: 483816 | G32: 1127106 | H32: 745091 | I32: 4696712 | J32: 1470584 | K32: 8523309
A33: 46143 | B33: 2869054 | C33: 4838895 | D33: 705490 | E33: 165518 | F33: 488531 | G33: 1128264 | H33: 753053 | I33: 4723876 | J33: 1485233 | K33: 8578957
A34: 46174 | B34: 2898492 | C34: 4906288 | D34: 712491 | E34: 168541 | F34: 492736 | G34: 1146646 | H34: 761554 | I34: 4780230 | J34: 1504646 | K34: 8685812
A35: 46204 | B35: 2908097 | C35: 4942701 | D35: 715489 | E35: 170517 | F35: 495360 | G35: 1149676 | H35: 766503 | I35: 4803325 | J35: 1521940 | K35: 8736804
A36: 46235
A37: 46266
A38: 46296
A39: 46327
A40: 46357

Sheet Partic%
A2: Indicador Serasa Experian de Inadimplência das Micro e Pequenas Empresas - Participação %
B3: Setor | F3: Região | K3: TOTAL
A4: Mês | B4: Comércio | C4: Serviço | D4: Indústria | E4: Demais | F4: Norte | G4: Nordeste | H4: Centro-Oeste | I4: Sudeste | J4: Sul
A5: =Geral!A5 -> 45292 | B5: =Geral!B5/Geral!$K5 -> 0.37989194 | C5: =Geral!C5/Geral!$K5 -> 0.52821316 | D5: =Geral!D5/Geral!$K5 -> 0.076728917 | E5: =Geral!E5/Geral!$K5 -> 0.015165985 | F5: =Geral!F5/Geral!$K5 -> 0.054385457 | G5: =Geral!G5/Geral!$K5 -> 0.16650549 | H5: =Geral!H5/Geral!$K5 -> 0.087379096 | I5: =Geral!I5/Geral!$K5 -> 0.52677449 | ... K5: =Geral!K5/Geral!$K5 -> 1
A6: =Geral!A6 -> 45323 | B6: =Geral!B6/Geral!$K6 -> 0.37877557 | C6: =Geral!C6/Geral!$K6 -> 0.52934189 | D6: =Geral!D6/Geral!$K6 -> 0.076629241 | E6: =Geral!E6/Geral!$K6 -> 0.015253294 | F6: =Geral!F6/Geral!$K6 -> 0.054331488 | G6: =Geral!G6/Geral!$K6 -> 0.16800358 | H6: =Geral!H6/Geral!$K6 -> 0.087789519 | I6: =Geral!I6/Geral!$K6 -> 0.52448267 | ... K6: =Geral!K6/Geral!$K6 -> 1
A7: =Geral!A7 -> 45352 | B7: =Geral!B7/Geral!$K7 -> 0.37768347 | C7: =Geral!C7/Geral!$K7 -> 0.53044257 | D7: =Geral!D7/Geral!$K7 -> 0.076610919 | E7: =Geral!E7/Geral!$K7 -> 0.015263038 | F7: =Geral!F7/Geral!$K7 -> 0.054520997 | G7: =Geral!G7/Geral!$K7 -> 0.16887182 | H7: =Geral!H7/Geral!$K7 -> 0.086526832 | I7: =Geral!I7/Geral!$K7 -> 0.52364604 | ... K7: =Geral!K7/Geral!$K7 -> 1
A8: =Geral!A8 -> 45383 | B8: =Geral!B8/Geral!$K8 -> 0.37570934 | C8: =Geral!C8/Geral!$K8 -> 0.53286259 | D8: =Geral!D8/Geral!$K8 -> 0.076235611 | E8: =Geral!E8/Geral!$K8 -> 0.015192454 | F8: =Geral!F8/Geral!$K8 -> 0.054996152 | G8: =Geral!G8/Geral!$K8 -> 0.16737555 | H8: =Geral!H8/Geral!$K8 -> 0.089220103 | I8: =Geral!I8/Geral!$K8 -> 0.52286252 | ... K8: =Geral!K8/Geral!$K8 -> 1
A9: =Geral!A9 -> 45413 | B9: =Geral!B9/Geral!$K9 -> 0.37463067 | C9: =Geral!C9/Geral!$K9 -> 0.53490958 | D9: =Geral!D9/Geral!$K9 -> 0.075441937 | E9: =Geral!E9/Geral!$K9 -> 0.015017804 | F9: =Geral!F9/Geral!$K9 -> 0.054601152 | G9: =Geral!G9/Geral!$K9 -> 0.16464981 | H9: =Geral!H9/Geral!$K9 -> 0.088325733 | I9: =Geral!I9/Geral!$K9 -> 0.5311057 | ... K9: =Geral!K9/Geral!$K9 -> 1
A10: =Geral!A10 -> 45444 | B10: =Geral!B10/Geral!$K10 -> 0.37279526 | C10: =Geral!C10/Geral!$K10 -> 0.53672882 | D10: =Geral!D10/Geral!$K10 -> 0.075147197 | E10: =Geral!E10/Geral!$K10 -> 0.015328719 | F10: =Geral!F10/Geral!$K10 -> 0.054448654 | G10: =Geral!G10/Geral!$K10 -> 0.16371206 | H10: =Geral!H10/Geral!$K10 -> 0.086930142 | I10: =Geral!I10/Geral!$K10 -> 0.53570421 | ... K10: =Geral!K10/Geral!$K10 -> 1
A11: =Geral!A11 -> 45474 | B11: =Geral!B11/Geral!$K11 -> 0.37183829 | C11: =Geral!C11/Geral!$K11 -> 0.5377578 | D11: =Geral!D11/Geral!$K11 -> 0.075002029 | E11: =Geral!E11/Geral!$K11 -> 0.015401879 | F11: =Geral!F11/Geral!$K11 -> 0.054530024 | G11: =Geral!G11/Geral!$K11 -> 0.16275932 | H11: =Geral!H11/Geral!$K11 -> 0.08755858 | I11: =Geral!I11/Geral!$K11 -> 0.53478113 | ... K11: =Geral!K11/Geral!$K11 -> 1
A12: =Geral!A12 -> 45505 | B12: =Geral!B12/Geral!$K12 -> 0.37151471 | C12: =Geral!C12/Geral!$K12 -> 0.53821067 | D12: =Geral!D12/Geral!$K12 -> 0.074799681 | E12: =Geral!E12/Geral!$K12 -> 0.015474941 | F12: =Geral!F12/Geral!$K12 -> 0.054970348 | G12: =Geral!G12/Geral!$K12 -> 0.16265715 | H12: =Geral!H12/Geral!$K12 -> 0.088149792 | I12: =Geral!I12/Geral!$K12 -> 0.53366175 | ... K12: =Geral!K12/Geral!$K12 -> 1
A13: =Geral!A13 -> 45536 | B13: =Geral!B13/Geral!$K13 -> 0.37085539 | C13: =Geral!C13/Geral!$K13 -> 0.53908066 | D13: =Geral!D13/Geral!$K13 -> 0.074623521 | E13: =Geral!E13/Geral!$K13 -> 0.015440427 | F13: =Geral!F13/Geral!$K13 -> 0.054846921 | G13: =Geral!G13/Geral!$K13 -> 0.16270334 | H13: =Geral!H13/Geral!$K13 -> 0.088422899 | I13: =Geral!I13/Geral!$K13 -> 0.53349634 | ... K13: =Geral!K13/Geral!$K13 -> 1
A14: =Geral!A14 -> 45566 | B14: =Geral!B14/Geral!$K14 -> 0.36956454 | C14: =Geral!C14/Geral!$K14 -> 0.54062889 | D14: =Geral!D14/Geral!$K14 -> 0.074412623 | E14: =Geral!E14/Geral!$K14 -> 0.015393944 | F14: =Geral!F14/Geral!$K14 -> 0.054932314 | G14: =Geral!G14/Geral!$K14 -> 0.16308041 | H14: =Geral!H14/Geral!$K14 -> 0.088859303 | I14: =Geral!I14/Geral!$K14 -> 0.53338215 | ... K14: =Geral!K14/Geral!$K14 -> 1
A15: =Geral!A15 -> 45597 | B15: =Geral!B15/Geral!$K15 -> 0.37084672 | C15: =Geral!C15/Geral!$K15 -> 0.52873623 | D15: =Geral!D15/Geral!$K15 -> 0.082043496 | E15: =Geral!E15/Geral!$K15 -> 0.018373548 | F15: =Geral!F15/Geral!$K15 -> 0.055154416 | G15: =Geral!G15/Geral!$K15 -> 0.15971757 | H15: =Geral!H15/Geral!$K15 -> 0.088517997 | I15: =Geral!I15/Geral!$K15 -> 0.5378347 | ... K15: =Geral!K15/Geral!$K15 -> 1
A16: =Geral!A16 -> 45627 | B16: =Geral!B16/Geral!$K16 -> 0.36999494 | C16: =Geral!C16/Geral!$K16 -> 0.52962735 | D16: =Geral!D16/Geral!$K16 -> 0.081816668 | E16: =Geral!E16/Geral!$K16 -> 0.018561042 | F16: =Geral!F16/Geral!$K16 -> 0.054629069 | G16: =Geral!G16/Geral!$K16 -> 0.15879211 | H16: =Geral!H16/Geral!$K16 -> 0.090482869 | I16: =Geral!I16/Geral!$K16 -> 0.53758988 | ... K16: =Geral!K16/Geral!$K16 -> 1
... A35: =Geral!A35 -> 46204 | B35: =Geral!B35/Geral!$K35 -> 0.33285593 | C35: =Geral!C35/Geral!$K35 -> 0.5657333 | D35: =Geral!D35/Geral!$K35 -> 0.081893676 | E35: =Geral!E35/Geral!$K35 -> 0.019517091 | F35: =Geral!F35/Geral!$K35 -> 0.056698079 | G35: =Geral!G35/Geral!$K35 -> 0.13159 | H35: =Geral!H35/Geral!$K35 -> 0.087732654 | I35: =Geral!I35/Geral!$K35 -> 0.54978056 | ... K35: =Geral!K35/Geral!$K35 -> 1
A36: =Geral!A36 -> 46235
A37: =Geral!A37 -> 46266
A38: =Geral!A38 -> 46296
A39: =Geral!A39 -> 46327
A40: =Geral!A40 -> 46357

Sheet Var.Mensal
A2: Indicador Serasa Experian de Inadimplência das Micro e Pequenas Empresas - Variação Mensal
B3: Setor | F3: Região | K3: TOTAL
A4: Mês | B4: Comércio | C4: Serviço | D4: Indústria | E4: Demais | F4: Norte | G4: Nordeste | H4: Centro-Oeste | I4: Sudeste | J4: Sul
A5: =Geral!A5 -> 45292 | B5: n.d | C5: n.d | D5: n.d | E5: n.d | F5: n.d | G5: n.d | H5: n.d | I5: n.d | J5: n.d | K5: n.d
A6: =Geral!A6 -> 45323 | B6: =Geral!B6/Geral!B5-1 -> -0.0054538786 | C6: =Geral!C6/Geral!C5-1 -> -0.00039115997 | D6: =Geral!D6/Geral!D5-1 -> -0.0038184317 | E6: =Geral!E6/Geral!E5-1 -> 0.0032197506 | F6: =Geral!F6/Geral!F5-1 -> -0.0035124867 | G6: =Geral!G6/Geral!G5-1 -> 0.0064518902 | H6: =Geral!H6/Geral!H5-1 -> 0.0021625361 | I6: =Geral!I6/Geral!I5-1 -> -0.0068623339 | ... K6: =Geral!K6/Geral!K5-1 -> -0.0025226538
A7: =Geral!A7 -> 45352 | B7: =Geral!B7/Geral!B6-1 -> 0.0005742273 | C7: =Geral!C7/Geral!C6-1 -> 0.0055539941 | D7: =Geral!D7/Geral!D6-1 -> 0.0032275182 | E7: =Geral!E7/Geral!E6-1 -> 0.004108472 | F7: =Geral!F7/Geral!F6-1 -> 0.0069675571 | G7: =Geral!G7/Geral!G6-1 -> 0.0086533615 | H7: =Geral!H7/Geral!H6-1 -> -0.010965538 | I7: =Geral!I7/Geral!I6-1 -> 0.0018667607 | ... K7: =Geral!K7/Geral!K6-1 -> 0.003467455
A8: =Geral!A8 -> 45383 | B8: =Geral!B8/Geral!B7-1 -> 0.0051175354 | C8: =Geral!C8/Geral!C7-1 -> 0.015008553 | D8: =Geral!D8/Geral!D7-1 -> 0.0054490091 | E8: =Geral!E8/Geral!E7-1 -> 0.0057262439 | F8: =Geral!F8/Geral!F7-1 -> 0.019204538 | G8: =Geral!G8/Geral!G7-1 -> 0.0014463214 | H8: =Geral!H8/Geral!H7-1 -> 0.041848942 | I8: =Geral!I8/Geral!I7-1 -> 0.0088870074 | ... K8: =Geral!K8/Geral!K7-1 -> 0.010398837
A9: =Geral!A9 -> 45413 | B9: =Geral!B9/Geral!B8-1 -> 0.016692669 | C9: =Geral!C9/Geral!C8-1 -> 0.023536884 | D9: =Geral!D9/Geral!D8-1 -> 0.0090049574 | E9: =Geral!E9/Geral!E8-1 -> 0.0078986325 | F9: =Geral!F9/Geral!F8-1 -> 0.012296781 | G9: =Geral!G9/Geral!G8-1 -> 0.0030153171 | H9: =Geral!H9/Geral!H8-1 -> 0.0093990231 | I9: =Geral!I9/Geral!I8-1 -> 0.035694809 | ... K9: =Geral!K9/Geral!K8-1 -> 0.019620015
A10: =Geral!A10 -> 45444 | B10: =Geral!B10/Geral!B9-1 -> 0.0020430094 | C10: =Geral!C10/Geral!C9-1 -> 0.010401182 | D10: =Geral!D10/Geral!D9-1 -> 0.0030423351 | E10: =Geral!E10/Geral!E9-1 -> 0.027823997 | F10: =Geral!F10/Geral!F9-1 -> 0.0041640182 | G10: =Geral!G10/Geral!G9-1 -> 0.0012412852 | H10: =Geral!H10/Geral!H9-1 -> -0.0089342938 | I10: =Geral!I10/Geral!I9-1 -> 0.01569522 | ... K10: =Geral!K10/Geral!K9-1 -> 0.0069764411
A11: =Geral!A11 -> 45474 | B11: =Geral!B11/Geral!B10-1 -> -0.0042991587 | C11: =Geral!C11/Geral!C10-1 -> 0.00017722881 | D11: =Geral!D11/Geral!D10-1 -> -0.0036650047 | E11: =Geral!E11/Geral!E10-1 -> 0.0030278502 | F11: =Geral!F11/Geral!F10-1 -> -0.00024475397 | G11: =Geral!G11/Geral!G10-1 -> -0.0075460788 | H11: =Geral!H11/Geral!H10-1 -> 0.0054800893 | I11: =Geral!I11/Geral!I10-1 -> -0.0034567101 | ... K11: =Geral!K11/Geral!K10-1 -> -0.0017365839
A12: =Geral!A12 -> 45505 | B12: =Geral!B12/Geral!B11-1 -> -0.0045867793 | C12: =Geral!C12/Geral!C11-1 -> -0.0028808132 | D12: =Geral!D12/Geral!D11-1 -> -0.0064076859 | E12: =Geral!E12/Geral!E11-1 -> 0.0010062367 | F12: =Geral!F12/Geral!F11-1 -> 0.0043250453 | G12: =Geral!G12/Geral!G11-1 -> -0.0043452355 | H12: =Geral!H12/Geral!H11-1 -> 0.0030072605 | I12: =Geral!I12/Geral!I11-1 -> -0.0058051738 | ... K12: =Geral!K12/Geral!K11-1 -> -0.0037198114
A13: =Geral!A13 -> 45536 | B13: =Geral!B13/Geral!B12-1 -> 0.0029160659 | C13: =Geral!C13/Geral!C12-1 -> 0.0063231334 | D13: =Geral!D13/Geral!D12-1 -> 0.002332927 | E13: =Geral!E13/Geral!E12-1 -> 0.002458323 | F13: =Geral!F13/Geral!F12-1 -> 0.0024431998 | G13: =Geral!G13/Geral!G12-1 -> 0.0049844095 | H13: =Geral!H13/Geral!H12-1 -> 0.0078118584 | I13: =Geral!I13/Geral!I12-1 -> 0.0043876725 | ... K13: =Geral!K13/Geral!K12-1 -> 0.0046990838
A14: =Geral!A14 -> 45566 | B14: =Geral!B14/Geral!B13-1 -> 0.0050260666 | C14: =Geral!C14/Geral!C13-1 -> 0.011433029 | D14: =Geral!D14/Geral!D13-1 -> 0.0056862419 | E14: =Geral!E14/Geral!E13-1 -> 0.0055002879 | F14: =Geral!F14/Geral!F13-1 -> 0.010106741 | G14: =Geral!G14/Geral!G13-1 -> 0.010873815 | H14: =Geral!H14/Geral!H13-1 -> 0.013514076 | I14: =Geral!I14/Geral!I13-1 -> 0.0083206471 | ... K14: =Geral!K14/Geral!K13-1 -> 0.0085365227
A15: =Geral!A15 -> 45597 | B15: =Geral!B15/Geral!B14-1 -> 0.0026586086 | C15: =Geral!C15/Geral!C14-1 -> -0.022788085 | D15: =Geral!D15/Geral!D14-1 -> 0.10165721 | E15: =Geral!E15/Geral!E14-1 -> 0.19259252 | F15: =Geral!F15/Geral!F14-1 -> 0.0032319029 | G15: =Geral!G15/Geral!G14-1 -> -0.021412101 | H15: =Geral!H15/Geral!H14-1 -> -0.0046459038 | I15: =Geral!I15/Geral!I14-1 -> 0.0075329964 | ... K15: =Geral!K15/Geral!K14-1 -> -0.00080803155
A16: =Geral!A16 -> 45627 | B16: =Geral!B16/Geral!B15-1 -> -0.0045987979 | C16: =Geral!C16/Geral!C15-1 -> -0.0006257698 | D16: =Geral!D16/Geral!D15-1 -> -0.0050656006 | E16: =Geral!E16/Geral!E15-1 -> 0.007873755 | F16: =Geral!F16/Geral!F15-1 -> -0.011810296 | G16: =Geral!G16/Geral!G15-1 -> -0.0080881968 | H16: =Geral!H16/Geral!H15-1 -> 0.019838972 | I16: =Geral!I16/Geral!I15-1 -> -0.0027613972 | ... K16: =Geral!K16/Geral!K15-1 -> -0.0023072471
A17: =Geral!A17 -> 45658 | B17: =Geral!B17/Geral!B16-1 -> 0.0098726613 | C17: =Geral!C17/Geral!C16-1 -> 0.019395465 | D17: =Geral!D17/Geral!D16-1 -> 0.017025971 | E17: =Geral!E17/Geral!E16-1 -> 0.013414714 | F17: =Geral!F17/Geral!F16-1 -> 0.027386172 | G17: =Geral!G17/Geral!G16-1 -> 0.019797721 | H17: =Geral!H17/Geral!H16-1 -> -0.030281634 | I17: =Geral!I17/Geral!I16-1 -> 0.020835189 | ... K17: =Geral!K17/Geral!K16-1 -> 0.015567203
... A35: =Geral!A35 -> 46204 | B35: =Geral!B35/Geral!B34-1 -> 0.0033137921 | C35: =Geral!C35/Geral!C34-1 -> 0.0074217005 | D35: =Geral!D35/Geral!D34-1 -> 0.0042077724 | E35: =Geral!E35/Geral!E34-1 -> 0.01172415 | F35: =Geral!F35/Geral!F34-1 -> 0.0053253669 | G35: =Geral!G35/Geral!G34-1 -> 0.0026424895 | H35: =Geral!H35/Geral!H34-1 -> 0.0064985543 | I35: =Geral!I35/Geral!I34-1 -> 0.0048313575 | ... K35: =Geral!K35/Geral!K34-1 -> 0.0058707234
A36: =Geral!A36 -> 46235
A37: =Geral!A37 -> 46266
A38: =Geral!A38 -> 46296
A39: =Geral!A39 -> 46327
A40: =Geral!A40 -> 46357

Sheet Var. Anual
A2: Indicador Serasa Experian de Inadimplência das Micro e Pequenas Empresas - Variação Anual
B3: Setor | F3: Região | K3: TOTAL
A4: Mês | B4: Comércio | C4: Serviço | D4: Indústria | E4: Demais | F4: Norte | G4: Nordeste | H4: Centro-Oeste | I4: Sudeste | J4: Sul
A5: =Geral!A5 -> 45292 | B5: n.d | C5: n.d | D5: n.d | E5: n.d | F5: n.d | G5: n.d | H5: n.d | I5: n.d | J5: n.d | K5: n.d
A6: =Geral!A6 -> 45323 | B6: n.d | C6: n.d | D6: n.d | E6: n.d | F6: n.d | G6: n.d | H6: n.d | I6: n.d | J6: n.d | K6: n.d
A7: =Geral!A7 -> 45352 | B7: n.d | C7: n.d | D7: n.d | E7: n.d | F7: n.d | G7: n.d | H7: n.d | I7: n.d | J7: n.d | K7: n.d
A8: =Geral!A8 -> 45383 | B8: n.d | C8: n.d | D8: n.d | E8: n.d | F8: n.d | G8: n.d | H8: n.d | I8: n.d | J8: n.d | K8: n.d
A9: =Geral!A9 -> 45413 | B9: n.d | C9: n.d | D9: n.d | E9: n.d | F9: n.d | G9: n.d | H9: n.d | I9: n.d | J9: n.d | K9: n.d
A10: =Geral!A10 -> 45444 | B10: n.d | C10: n.d | D10: n.d | E10: n.d | F10: n.d | G10: n.d | H10: n.d | I10: n.d | J10: n.d | K10: n.d
A11: =Geral!A11 -> 45474 | B11: n.d | C11: n.d | D11: n.d | E11: n.d | F11: n.d | G11: n.d | H11: n.d | I11: n.d | J11: n.d | K11: n.d
A12: =Geral!A12 -> 45505 | B12: n.d | C12: n.d | D12: n.d | E12: n.d | F12: n.d | G12: n.d | H12: n.d | I12: n.d | J12: n.d | K12: n.d
A13: =Geral!A13 -> 45536 | B13: n.d | C13: n.d | D13: n.d | E13: n.d | F13: n.d | G13: n.d | H13: n.d | I13: n.d | J13: n.d | K13: n.d
A14: =Geral!A14 -> 45566 | B14: n.d | C14: n.d | D14: n.d | E14: n.d | F14: n.d | G14: n.d | H14: n.d | I14: n.d | J14: n.d | K14: n.d
A15: =Geral!A15 -> 45597 | B15: n.d | C15: n.d | D15: n.d | E15: n.d | F15: n.d | G15: n.d | H15: n.d | I15: n.d | J15: n.d | K15: n.d
A16: =Geral!A16 -> 45627 | B16: n.d | C16: n.d | D16: n.d | E16: n.d | F16: n.d | G16: n.d | H16: n.d | I16: n.d | J16: n.d | K16: n.d
A17: =Geral!A17 -> 45658 | B17: =Geral!B17/Geral!B5-1 -> 0.026027972 | C17: =Geral!C17/Geral!C5-1 -> 0.066254187 | D17: =Geral!D17/Geral!D5-1 -> 0.13128398 | E17: =Geral!E17/Geral!E5-1 -> 0.29382584 | F17: =Geral!F17/Geral!F5-1 -> 0.076543549 | G17: =Geral!G17/Geral!G5-1 -> 0.014544933 | H17: =Geral!H17/Geral!H5-1 -> 0.047517543 | I17: =Geral!I17/Geral!I5-1 -> 0.08677303 | ... K17: =Geral!K17/Geral!K5-1 -> 0.059413586
A18: =Geral!A18 -> 45689 | B18: =Geral!B18/Geral!B6-1 -> 0.041675262 | C18: =Geral!C18/Geral!C6-1 -> 0.094809514 | D18: =Geral!D18/Geral!D6-1 -> 0.15613613 | E18: =Geral!E18/Geral!E6-1 -> 0.31815046 | F18: =Geral!F18/Geral!F6-1 -> 0.10405551 | G18: =Geral!G18/Geral!G6-1 -> 0.023172444 | H18: =Geral!H18/Geral!H6-1 -> 0.069642153 | I18: =Geral!I18/Geral!I6-1 -> 0.11708056 | ... K18: =Geral!K18/Geral!K6-1 -> 0.082789655
A19: =Geral!A19 -> 45717 | B19: =Geral!B19/Geral!B7-1 -> 0.056071577 | C19: =Geral!C19/Geral!C7-1 -> 0.11606187 | D19: =Geral!D19/Geral!D7-1 -> 0.17376884 | E19: =Geral!E19/Geral!E7-1 -> 0.34151319 | F19: =Geral!F19/Geral!F7-1 -> 0.12276447 | G19: =Geral!G19/Geral!G7-1 -> 0.034204514 | H19: =Geral!H19/Geral!H7-1 -> 0.10733399 | I19: =Geral!I19/Geral!I7-1 -> 0.1366657 | ... K19: =Geral!K19/Geral!K7-1 -> 0.10126658
A20: =Geral!A20 -> 45748 | B20: =Geral!B20/Geral!B8-1 -> 0.070127879 | C20: =Geral!C20/Geral!C8-1 -> 0.13786783 | D20: =Geral!D20/Geral!D8-1 -> 0.20191322 | E20: =Geral!E20/Geral!E8-1 -> 0.37168087 | F20: =Geral!F20/Geral!F8-1 -> 0.13196448 | G20: =Geral!G20/Geral!G8-1 -> 0.057217733 | H20: =Geral!H20/Geral!H8-1 -> 0.090598685 | I20: =Geral!I20/Geral!I8-1 -> 0.15772354 | ... K20: =Geral!K20/Geral!K8-1 -> 0.12085203
A21: =Geral!A21 -> 45778 | B21: =Geral!B21/Geral!B9-1 -> 0.063367878 | C21: =Geral!C21/Geral!C9-1 -> 0.14180817 | D21: =Geral!D21/Geral!D9-1 -> 0.21966763 | E21: =Geral!E21/Geral!E9-1 -> 0.38976192 | F21: =Geral!F21/Geral!F9-1 -> 0.13816405 | G21: =Geral!G21/Geral!G9-1 -> 0.068787812 | H21: =Geral!H21/Geral!H9-1 -> 0.11182711 | I21: =Geral!I21/Geral!I9-1 -> 0.13922109 | ... K21: =Geral!K21/Geral!K9-1 -> 0.12201962
A22: =Geral!A22 -> 45809 | B22: =Geral!B22/Geral!B10-1 -> 0.070979878 | C22: =Geral!C22/Geral!C10-1 -> 0.15042416 | D22: =Geral!D22/Geral!D10-1 -> 0.23377553 | E22: =Geral!E22/Geral!E10-1 -> 0.37888099 | F22: =Geral!F22/Geral!F10-1 -> 0.15009045 | G22: =Geral!G22/Geral!G10-1 -> 0.076059609 | H22: =Geral!H22/Geral!H10-1 -> 0.14183916 | I22: =Geral!I22/Geral!I10-1 -> 0.13677151 | ... K22: =Geral!K22/Geral!K10-1 -> 0.13057328
A23: =Geral!A23 -> 45839 | B23: =Geral!B23/Geral!B11-1 -> 0.096803533 | C23: =Geral!C23/Geral!C11-1 -> 0.18802414 | D23: =Geral!D23/Geral!D11-1 -> 0.27127507 | E23: =Geral!E23/Geral!E11-1 -> 0.41031542 | F23: =Geral!F23/Geral!F11-1 -> 0.24962574 | G23: =Geral!G23/Geral!G11-1 -> 0.10767303 | H23: =Geral!H23/Geral!H11-1 -> 0.16609507 | I23: =Geral!I23/Geral!I11-1 -> 0.16654037 | ... K23: =Geral!K23/Geral!K11-1 -> 0.16377252
A24: =Geral!A24 -> 45870 | B24: =Geral!B24/Geral!B12-1 -> 0.11133991 | C24: =Geral!C24/Geral!C12-1 -> 0.21337027 | D24: =Geral!D24/Geral!D12-1 -> 0.29849935 | E24: =Geral!E24/Geral!E12-1 -> 0.43402837 | F24: =Geral!F24/Geral!F12-1 -> 0.28157317 | G24: =Geral!G24/Geral!G12-1 -> 0.11851229 | H24: =Geral!H24/Geral!H12-1 -> 0.18068264 | I24: =Geral!I24/Geral!I12-1 -> 0.19026966 | ... K24: =Geral!K24/Geral!K12-1 -> 0.18524679
A25: =Geral!A25 -> 45901 | B25: =Geral!B25/Geral!B13-1 -> 0.13400116 | C25: =Geral!C25/Geral!C13-1 -> 0.2545489 | D25: =Geral!D25/Geral!D13-1 -> 0.34223863 | E25: =Geral!E25/Geral!E13-1 -> 0.47687695 | F25: =Geral!F25/Geral!F13-1 -> 0.3282427 | G25: =Geral!G25/Geral!G13-1 -> 0.14805292 | H25: =Geral!H25/Geral!H13-1 -> 0.20836815 | I25: =Geral!I25/Geral!I13-1 -> 0.22481666 | ... K25: =Geral!K25/Geral!K13-1 -> 0.21981968
A26: =Geral!A26 -> 45931 | B26: =Geral!B26/Geral!B14-1 -> 0.15740493 | C26: =Geral!C26/Geral!C14-1 -> 0.28783101 | D26: =Geral!D26/Geral!D14-1 -> 0.38106084 | E26: =Geral!E26/Geral!E14-1 -> 0.52032071 | F26: =Geral!F26/Geral!F14-1 -> 0.36229686 | G26: =Geral!G26/Geral!G14-1 -> 0.17472863 | H26: =Geral!H26/Geral!H14-1 -> 0.23558803 | I26: =Geral!I26/Geral!I14-1 -> 0.25357564 | ... K26: =Geral!K26/Geral!K14-1 -> 0.25014657
A27: =Geral!A27 -> 45962 | B27: =Geral!B27/Geral!B15-1 -> 0.17206584 | C27: =Geral!C27/Geral!C15-1 -> 0.35724723 | D27: =Geral!D27/Geral!D15-1 -> 0.28924543 | E27: =Geral!E27/Geral!E15-1 -> 0.31076908 | F27: =Geral!F27/Geral!F15-1 -> 0.39613587 | G27: =Geral!G27/Geral!G15-1 -> 0.22814201 | H27: =Geral!H27/Geral!H15-1 -> 0.27327737 | I27: =Geral!I27/Geral!I15-1 -> 0.27528186 | ... K27: =Geral!K27/Geral!K15-1 -> 0.28214025
A28: =Geral!A28 -> 45992 | B28: =Geral!B28/Geral!B16-1 -> 0.18761559 | C28: =Geral!C28/Geral!C16-1 -> 0.37058059 | D28: =Geral!D28/Geral!D16-1 -> 0.30854355 | E28: =Geral!E28/Geral!E16-1 -> 0.31850294 | F28: =Geral!F28/Geral!F16-1 -> 0.42355066 | G28: =Geral!G28/Geral!G16-1 -> 0.2469818 | H28: =Geral!H28/Geral!H16-1 -> 0.26474776 | I28: =Geral!I28/Geral!I16-1 -> 0.29054225 | ... K28: =Geral!K28/Geral!K16-1 -> 0.29684219
... A35: =Geral!A35 -> 46204 | B35: =Geral!B35/Geral!B23-1 -> 0.094153921 | C35: =Geral!C35/Geral!C23-1 -> 0.18714791 | D35: =Geral!D35/Geral!D23-1 -> 0.1514442 | E35: =Geral!E35/Geral!E23-1 -> 0.20456488 | F35: =Geral!F35/Geral!F23-1 -> 0.11546967 | G35: =Geral!G35/Geral!G23-1 -> -0.021478223 | H35: =Geral!H35/Geral!H23-1 -> 0.15195012 | I35: =Geral!I35/Geral!I23-1 -> 0.18145887 | ... K35: =Geral!K35/Geral!K23-1 -> 0.15195888
A36: =Geral!A36 -> 46235
A37: =Geral!A37 -> 46266
A38: =Geral!A38 -> 46296
A39: =Geral!A39 -> 46327
A40: =Geral!A40 -> 46357

Sheet UF Geral
A2: Indicador Serasa Experian de Inadimplência das Micro e Pequenas Empresas por Unidades da Federação
A3: UF | B3: AC | C3: AL | D3: AM | E3: AP | F3: BA | G3: CE | H3: DF | I3: ES | J3: GO | K3: MA | L3: MG | M3: MS | N3: MT | O3: PA | P3: PB | Q3: PE | R3: PI | S3: PR | T3: RJ | U3: RN | V3: RO | W3: RR | X3: RS | Y3: SC | Z3: SE | AA3: SP | AB3: TO | AC3: Total Geral
A4: ='Var. Anual'!A5 -> 45292 | B4: 13955 | C4: 81440 | D4: 70393 | E4: 14697 | F4: 298616 | G4: 150403 | H4: 121557 | I4: 115680 | J4: 215341 | K4: 110920 | L4: 574870 | M4: 78543 | N4: 133914 | O4: 143380 | P4: 62320 | Q4: 190143 | R4: 41592 | S4: 407507 | T4: 563835 | U4: 68013 | V4: 50898 | W4: 9133 | X4: 349706 | Y4: 279867 | Z4: 43378 | AA4: 2057462 | AB4: 39467 | AC4: =SUM(B4:AB4) -> 6287030
A5: ='Var. Anual'!A6 -> 45323 | B5: 13959 | C5: 84031 | D5: 68283 | E5: 14736 | F5: 301507 | G5: 149602 | H5: 122141 | I5: 117215 | J5: 214962 | K5: 110996 | L5: 584245 | M5: 78669 | N5: 134771 | O5: 144085 | P5: 62775 | Q5: 190730 | R5: 41668 | S5: 406912 | T5: 558853 | U5: 68751 | V5: 50908 | W5: 9169 | X5: 350330 | Y5: 279964 | Z5: 43519 | AA5: 2028807 | AB5: 39582 | AC5: 6271170
A6: ='Var. Anual'!A7 -> 45352 | B6: 14015 | C6: 85735 | D6: 68696 | E6: 14753 | F6: 304381 | G6: 151893 | H6: 126184 | I6: 118397 | J6: 203867 | K6: 111562 | L6: 592753 | M6: 79428 | N6: 135027 | O6: 145360 | P6: 63237 | Q6: 190683 | R6: 42142 | S6: 409948 | T6: 559350 | U6: 68999 | V6: 51193 | W6: 9238 | X6: 353786 | Y6: 283623 | Z6: 44064 | AA6: 2024760 | AB6: 39841 | AC6: =SUM(B6:AB6) -> 6292915
A7: ='Var. Anual'!A8 -> 45383 | B7: 14130 | C7: 81935 | D7: 72232 | E7: 14895 | F7: 306361 | G7: 152631 | H7: 128958 | I7: 121813 | J7: 205228 | K7: 111757 | L7: 597453 | M7: 80293 | N7: 152814 | O7: 146835 | P7: 63974 | Q7: 191957 | R7: 42293 | S7: 413312 | T7: 567973 | U7: 69326 | V7: 51933 | W7: 9248 | X7: 353618 | Y7: 285668 | Z7: 43999 | AA7: 2037306 | AB7: 40412 | AC7: 6358354
A8: ='Var. Anual'!A9 -> 45413 | B8: 14168 | C8: 81624 | D8: 74120 | E8: 14928 | F8: 306318 | G8: 152906 | H8: 133071 | I8: 120580 | J8: 205241 | K8: 112595 | L8: 593896 | M8: 80958 | N8: 153355 | O8: 149270 | P8: 64299 | Q8: 193121 | R8: 42646 | S8: 414700 | T8: 567971 | U8: 69764 | V8: 51537 | W8: 9336 | X8: 342786 | Y8: 288353 | Z8: 44169 | AA8: 2160767 | AB8: 40626 | AC8: 6483105
A9: ='Var. Anual'!A10 -> 45444 | B9: 14240 | C9: 81600 | D9: 74633 | E9: 14929 | F9: 307072 | G9: 153524 | H9: 134758 | I9: 121698 | J9: 198001 | K9: 112628 | L9: 584172 | M9: 81506 | N9: 153244 | O9: 149745 | P9: 64908 | Q9: 192019 | R9: 42785 | S9: 416411 | T9: 572028 | U9: 70095 | V9: 51778 | W9: 9386 | X9: 333153 | Y9: 289779 | Z9: 44136 | AA9: 2219358 | AB9: 40748 | AC9: =SUM(B9:AB9) -> 6528334
A10: ='Var. Anual'!A11 -> 45474 | B10: 14145 | C10: 78833 | D10: 74714 | E10: 14859 | F10: 303664 | G10: 151885 | H10: 136107 | I10: 120620 | J10: 197637 | K10: 114584 | L10: 578159 | M10: 81203 | N10: 155672 | O10: 150047 | P10: 64413 | Q10: 191179 | R10: 42412 | S10: 415914 | T10: 574999 | U10: 69795 | V10: 51662 | W10: 9337 | X10: 343339 | Y10: 285884 | Z10: 43937 | AA10: 2211389 | AB10: 40608 | AC10: =SUM(B10:AB10) -> 6516997
A11: ='Var. Anual'!A12 -> 45505 | B11: 14143 | C11: 74585 | D11: 75253 | E11: 14814 | F11: 302446 | G11: 150925 | H11: 137223 | I11: 120123 | J11: 197242 | K11: 114851 | L11: 574335 | M11: 81107 | N11: 156763 | O11: 150381 | P11: 66265 | Q11: 190652 | R11: 42761 | S11: 413980 | T11: 572283 | U11: 69857 | V11: 52396 | W11: 9314 | X11: 343192 | Y11: 285311 | Z11: 43751 | AA11: 2198194 | AB11: 40608 | AC11: =SUM(B11:AB11) -> 6492755
A12: ='Var. Anual'!A13 -> 45536 | B12: 14105 | C12: 75088 | D12: 75495 | E12: 14805 | F12: 305538 | G12: 151669 | H12: 138790 | I12: 121167 | J12: 198425 | K12: 115687 | L12: 577519 | M12: 81557 | N12: 158034 | O12: 150591 | P12: 67162 | Q12: 190434 | R12: 42849 | S12: 414119 | T12: 574450 | U12: 70058 | V12: 52628 | W12: 9359 | X12: 346234 | Y12: 286830 | Z12: 42872 | AA12: 2207002 | AB12: 40798 | AC12: =SUM(B12:AB12) -> 6523265
A13: ='Var. Anual'!A14 -> 45566 | B13: 14237 | C13: 75340 | D13: 76086 | E13: 14885 | F13: 313144 | G13: 153628 | H13: 142018 | I13: 122137 | J13: 200276 | K13: 116594 | L13: 584160 | M13: 82556 | N13: 159751 | O13: 151976 | P13: 68762 | Q13: 187966 | R13: 43492 | S13: 417944 | T13: 575161 | U13: 70590 | V13: 52993 | W13: 9522 | X13: 343431 | Y13: 289585 | Z13: 43382 | AA13: 2227637 | AB13: 41698 | AC13: =SUM(B13:AB13) -> 6578951
A14: ='Var. Anual'!A15 -> 45597 | B14: 13379 | C14: 75110 | D14: 76576 | E14: 14659 | F14: 304015 | G14: 153225 | H14: 142839 | I14: 121974 | J14: 197973 | K14: 104496 | L14: 589210 | M14: 82630 | N14: 158443 | O14: 152914 | P14: 69927 | Q14: 187194 | R14: 43652 | S14: 415429 | T14: 579233 | U14: 71144 | V14: 53591 | W14: 9482 | X14: 345988 | Y14: 282314 | Z14: 41162 | AA14: 2245112 | AB14: 41964 | AC14: =SUM(B14:AB14) -> 6573635
A15: ='Var. Anual'!A16 -> 45627 | B15: 13229 | C15: 74382 | D15: 75588 | E15: 14615 | F15: 301189 | G15: 153415 | H15: 141820 | I15: 118439 | J15: 210996 | K15: 106180 | L15: 581958 | M15: 81702 | N15: 158911 | O15: 154170 | P15: 69524 | Q15: 181991 | R15: 43958 | S15: 412437 | T15: 571934 | U15: 70067 | V15: 49186 | W15: 9500 | X15: 344052 | Y15: 283068 | Z15: 40727 | AA15: 2253435 | AB15: 41995 | AC15: 6558468
A16: ='Var. Anual'!A17 -> 45658 | B16: 13535 | C16: 75933 | D16: 78186 | E16: 14843 | F16: 305705 | G16: 156715 | H16: 145067 | I16: 119927 | J16: 213657 | K16: 108742 | L16: 598890 | M16: 85455 | N16: 131280 | O16: 158447 | P16: 72002 | Q16: 185548 | R16: 44926 | S16: 420748 | T16: 589651 | U16: 71847 | V16: 50322 | W16: 9627 | X16: 346984 | Y16: 288002 | Z16: 40633 | AA16: 2290758 | AB16: 43135 | AC16: 6660565
A17: ='Var. Anual'!A18 -> 45689 | B17: 13851 | C17: 76582 | D17: 80901 | E17: 15191 | F17: 310540 | G17: 157992 | H17: 148988 | I17: 120867 | J17: 218662 | K17: 110240 | L17: 613777 | M17: 88237 | N17: 132997 | O17: 161473 | P17: 73522 | Q17: 189150 | R17: 45456 | S17: 426804 | T17: 604213 | U17: 73656 | V17: 50827 | W17: 9813 | X17: 353721 | Y17: 292568 | Z17: 40855 | AA17: 2335355 | AB17: 44120 | AC17: 6790358
A18: ='Var. Anual'!A19 -> 45717 | B18: 14207 | C18: 76234 | D18: 83263 | E18: 15412 | F18: 315948 | G18: 162522 | H18: 152909 | I18: 121748 | J18: 223452 | K18: 113721 | L18: 628507 | M18: 90737 | N18: 135852 | O18: 165197 | P18: 74782 | Q18: 192633 | R18: 46531 | S18: 436741 | T18: 617299 | U18: 75165 | V18: 51797 | W18: 10071 | X18: 361595 | Y18: 299021 | Z18: 41509 | AA18: 2378055 | AB18: 45269 | AC18: 6930177
A19: ='Var. Anual'!A20 -> 45748 | B19: 14662 | C19: 76669 | D19: 86151 | E19: 16006 | F19: 321935 | G19: 167028 | H19: 158882 | I19: 124562 | J19: 231231 | K19: 115873 | L19: 648868 | M19: 88442 | N19: 140134 | O19: 169818 | P19: 78507 | Q19: 197015 | R19: 47917 | S19: 452947 | T19: 639016 | U19: 77895 | V19: 51894 | W19: 10420 | X19: 377897 | Y19: 307380 | Z19: 42287 | AA19: 2436458 | AB19: 46880 | AC19: 7126774
A20: ='Var. Anual'!A21 -> 45778 | B20: 14930 | C20: 77113 | D20: 88617 | E20: 16210 | F20: 326338 | G20: 170250 | H20: 162526 | I20: 123629 | J20: 234313 | K20: 116232 | L20: 665374 | M20: 98640 | N20: 141181 | O20: 172067 | P20: 81382 | Q20: 200333 | R20: 48240 | S20: 461735 | T20: 650646 | U20: 79100 | V20: 52629 | W20: 10549 | X20: 388770 | Y20: 320662 | Z20: 41881 | AA20: 2482933 | AB20: 47891 | AC20: 7274171
A21: ='Var. Anual'!A22 -> 45809 | B21: 14990 | C21: 77242 | D21: 90392 | E21: 16224 | F21: 326546 | G21: 172057 | H21: 165442 | I21: 124035 | J21: 238704 | K21: 117326 | L21: 678991 | M21: 101151 | N21: 142707 | O21: 174195 | P21: 84427 | Q21: 202138 | R21: 48424 | S21: 475130 | T21: 664670 | U21: 79800 | V21: 53273 | W21: 10890 | X21: 395230 | Y21: 327948 | Z21: 42097 | AA21: 2507885 | AB21: 48846 | AC21: 7380760
A22: ='Var. Anual'!A23 -> 45839 | B22: 15289 | C22: 78661 | D22: 118181 | E22: 16797 | F22: 332646 | G22: 176020 | H22: 170573 | I22: 127201 | J22: 244104 | K22: 119734 | L22: 697789 | M22: 104350 | N22: 146369 | O22: 178584 | P22: 86567 | Q22: 206810 | R22: 49470 | S22: 488520 | T22: 685956 | U22: 82212 | V22: 53232 | W22: 11245 | X22: 408655 | Y22: 337150 | Z22: 42791 | AA22: 2554642 | AB22: 50754 | AC22: 7584302
A23: ='Var. Anual'!A24 -> 45870 | B23: 15559 | C23: 66694 | D23: 123590 | E23: 17024 | F23: 337713 | G23: 179700 | H23: 173488 | I23: 128687 | J23: 247451 | K23: 121526 | L23: 711206 | M23: 106724 | N23: 148083 | O23: 183008 | P23: 88494 | Q23: 209798 | R23: 50313 | S23: 494709 | T23: 698579 | U23: 83508 | V23: 53888 | W23: 11476 | X23: 418483 | Y23: 343714 | Z23: 43507 | AA23: 2585735 | AB23: 52860 | AC23: 7695517
A24: ='Var. Anual'!A25 -> 45901 | B24: 16085 | C24: 70858 | D24: 127297 | E24: 17466 | F24: 347755 | G24: 186035 | H24: 179547 | I24: 130474 | J24: 253745 | K24: 124749 | L24: 741420 | M24: 111342 | N24: 152360 | O24: 188202 | P24: 91802 | Q24: 215494 | R24: 51596 | S24: 511454 | T24: 724783 | U24: 86182 | V24: 55159 | W24: 11943 | X24: 437254 | Y24: 355260 | Z24: 44023 | AA24: 2665854 | AB24: 59068 | AC24: =SUM(B24:AB24) -> 7957207
A25: ='Var. Anual'!A26 -> 45931 | B25: 16534 | C25: 73578 | D25: 131828 | E25: 19057 | F25: 359007 | G25: 192630 | H25: 186968 | I25: 133489 | J25: 262510 | K25: 127471 | L25: 772867 | M25: 115216 | N25: 157632 | O25: 193803 | P25: 95754 | Q25: 223956 | R25: 53435 | S25: 527940 | T25: 756575 | U25: 89257 | V25: 56994 | W25: 12432 | X25: 455112 | Y25: 367665 | Z25: 45276 | AA25: 2735985 | AB25: 61682 | AC25: =SUM(B25:AB25) -> 8224653
A26: ='Var. Anual'!A27 -> 45962 | B26: 17250 | C26: 75514 | D26: 134986 | E26: 20589 | F26: 366837 | G26: 197274 | H26: 192147 | I26: 134239 | J26: 268857 | K26: 129224 | L26: 795854 | M26: 119333 | N26: 160564 | O26: 199202 | P26: 98024 | Q26: 231509 | R26: 54750 | S26: 542463 | T26: 778160 | U26: 91067 | V26: 58147 | W26: 12862 | X26: 465583 | Y26: 374932 | Z26: 45258 | AA26: 2800543 | AB26: 63154 | AC26: 8428322
A27: ='Var. Anual'!A28 -> 45992 | B27: 17187 | C27: 76146 | D27: 135119 | E27: 21771 | F27: 369665 | G27: 200095 | H27: 194949 | I27: 134548 | J27: 272378 | K27: 130644 | L27: 806590 | M27: 121021 | N27: 162190 | O27: 200689 | P27: 98914 | Q27: 230582 | R27: 55127 | S27: 545551 | T27: 792599 | U27: 91999 | V27: 58466 | W27: 13043 | X27: 469945 | Y27: 380432 | Z27: 45476 | AA27: 2816413 | AB27: 63759 | AC27: 8505298
A28: ='Var. Anual'!A29 -> 46023 | B28: 13019 | C28: 61629 | D28: 136023 | E28: 14843 | F28: 308689 | G28: 173908 | H28: 205295 | I28: 126113 | J28: 226964 | K28: 101269 | L28: 815147 | M28: 122679 | N28: 164535 | O28: 168466 | P28: 85046 | Q28: 198592 | R28: 53178 | S28: 552314 | T28: 799699 | U28: 85072 | V28: 61940 | W28: 10013 | X28: 474966 | Y28: 387126 | Z28: 38168 | AA28: 2844014 | AB28: 64737 | AC28: 8293444
A29: ='Var. Anual'!A30 -> 46054 | B29: 13087 | C29: 62067 | D29: 138544 | E29: 14881 | F29: 310907 | G29: 174501 | H29: 206753 | I29: 126517 | J29: 228983 | K29: 101531 | L29: 825520 | M29: 124565 | N29: 170321 | O29: 169397 | P29: 85491 | Q29: 200615 | R29: 53722 | S29: 560238 | T29: 810051 | U29: 86202 | V29: 62364 | W29: 10075 | X29: 481644 | Y29: 393314 | Z29: 38340 | AA29: 2872405 | AB29: 65295 | AC29: 8387330
A30: ='Var. Anual'!A31 -> 46082 | B30: 13188 | C30: 60445 | D30: 139696 | E30: 14924 | F30: 311420 | G30: 177078 | H30: 208096 | I30: 127123 | J30: 231324 | K30: 102303 | L30: 833071 | M30: 126006 | N30: 171312 | O30: 171521 | P30: 86419 | Q30: 200527 | R30: 54342 | S30: 564569 | T30: 814112 | U30: 86591 | V30: 63036 | W30: 10149 | X30: 487483 | Y30: 398681 | Z30: 38372 | AA30: 2884162 | AB30: 66708 | AC30: 8442658
A31: ='Var. Anual'!A32 -> 46113 | B31: 13270 | C31: 61246 | D31: 140716 | E31: 15003 | F31: 312962 | G31: 179451 | H31: 209519 | I31: 128358 | J31: 233913 | K31: 104038 | L31: 841082 | M31: 127362 | N31: 174297 | O31: 173656 | P31: 86639 | Q31: 201600 | R31: 54966 | S31: 570767 | T31: 818385 | U31: 87462 | V31: 63195 | W31: 10285 | X31: 494923 | Y31: 404894 | Z31: 38742 | AA31: 2908887 | AB31: 67691 | AC31: 8523309
A32: ='Var. Anual'!A33 -> 46143 | B32: 13337 | C32: 57009 | D32: 141579 | E32: 15089 | F32: 314249 | G32: 180537 | H32: 211450 | I32: 128285 | J32: 236784 | K32: 104476 | L32: 846285 | M32: 128794 | N32: 176025 | O32: 174810 | P32: 86674 | Q32: 203496 | R32: 55041 | S32: 574913 | T32: 822221 | U32: 87957 | V32: 63958 | W32: 10369 | X32: 499214 | Y32: 411106 | Z32: 38825 | AA32: 2927085 | AB32: 69389 | AC32: 8578957
A33: ='Var. Anual'!A34 -> 46174 | B33: 13383 | C33: 57399 | D33: 142522 | E33: 15122 | F33: 318291 | G33: 181845 | H33: 213319 | I33: 130422 | J33: 239379 | K33: 113491 | L33: 865586 | M33: 130561 | N33: 178295 | O33: 176478 | P33: 87324 | Q33: 205445 | R33: 55413 | S33: 582819 | T33: 827245 | U33: 88194 | V33: 64134 | W33: 10449 | X33: 504129 | Y33: 417698 | Z33: 39244 | AA33: 2956977 | AB33: 70648 | AC33: 8685812
A34: ='Var. Anual'!A35 -> 46204 | B34: 13362 | C34: 57480 | D34: 143397 | E34: 15118 | F34: 319349 | G34: 182324 | H34: 214395 | I34: 131099 | J34: 241257 | K34: 113448 | L34: 872754 | M34: 131420 | N34: 179431 | O34: 176784 | P34: 87429 | Q34: 206205 | R34: 55401 | S34: 588156 | T34: 823089 | U34: 88386 | V34: 64671 | W34: 10480 | X34: 509489 | Y34: 424295 | Z34: 39654 | AA34: 2976383 | AB34: 71548 | AC34: 8736804
A35: ='Var. Anual'!A36 -> 46235
A36: ='Var. Anual'!A37 -> 46266
A37: ='Var. Anual'!A38 -> 46296
A38: ='Var. Anual'!A39 -> 46327
A39: ='Var. Anual'!A40 -> 46357

Sheet UF Part%
A2: Indicador Serasa Experian de Inadimplência das Micro e Pequenas Empresas por Unidades da Federação - Participação%
A3: UF | B3: AC | C3: AL | D3: AM | E3: AP | F3: BA | G3: CE | H3: DF | I3: ES | J3: GO | K3: MA | L3: MG | M3: MS | N3: MT | O3: PA | P3: PB | Q3: PE | R3: PI | S3: PR | T3: RJ | U3: RN | V3: RO | W3: RR | X3: RS | Y3: SC | Z3: SE | AA3: SP | AB3: TO | AC3: Total Geral
A4: ='UF Geral'!A4 -> 45292 | B4: ='UF Geral'!B4/'UF Geral'!$AC4 -> 0.002219649 | C4: ='UF Geral'!C4/'UF Geral'!$AC4 -> 0.012953652 | D4: ='UF Geral'!D4/'UF Geral'!$AC4 -> 0.011196543 | E4: ='UF Geral'!E4/'UF Geral'!$AC4 -> 0.0023376698 | F4: ='UF Geral'!F4/'UF Geral'!$AC4 -> 0.047497149 | G4: ='UF Geral'!G4/'UF Geral'!$AC4 -> 0.023922743 | H4: ='UF Geral'!H4/'UF Geral'!$AC4 -> 0.019334567 | I4: ='UF Geral'!I4/'UF Geral'!$AC4 -> 0.018399785 | ... AC4: ='UF Geral'!AC4/'UF Geral'!$AC4 -> 1
A5: ='UF Geral'!A5 -> 45323 | B5: ='UF Geral'!B5/'UF Geral'!$AC5 -> 0.0022259004 | C5: ='UF Geral'!C5/'UF Geral'!$AC5 -> 0.013399573 | D5: ='UF Geral'!D5/'UF Geral'!$AC5 -> 0.010888399 | E5: ='UF Geral'!E5/'UF Geral'!$AC5 -> 0.0023498008 | F5: ='UF Geral'!F5/'UF Geral'!$AC5 -> 0.048078269 | G5: ='UF Geral'!G5/'UF Geral'!$AC5 -> 0.023855517 | H5: ='UF Geral'!H5/'UF Geral'!$AC5 -> 0.019476589 | I5: ='UF Geral'!I5/'UF Geral'!$AC5 -> 0.01869109 | ... AC5: ='UF Geral'!AC5/'UF Geral'!$AC5 -> 1
A6: ='UF Geral'!A6 -> 45352 | B6: ='UF Geral'!B6/'UF Geral'!$AC6 -> 0.0022271078 | C6: ='UF Geral'!C6/'UF Geral'!$AC6 -> 0.013624052 | D6: ='UF Geral'!D6/'UF Geral'!$AC6 -> 0.010916404 | E6: ='UF Geral'!E6/'UF Geral'!$AC6 -> 0.0023443825 | F6: ='UF Geral'!F6/'UF Geral'!$AC6 -> 0.04836884 | G6: ='UF Geral'!G6/'UF Geral'!$AC6 -> 0.024137145 | H6: ='UF Geral'!H6/'UF Geral'!$AC6 -> 0.020051757 | I6: ='UF Geral'!I6/'UF Geral'!$AC6 -> 0.018814333 | ... AC6: ='UF Geral'!AC6/'UF Geral'!$AC6 -> 1
A7: ='UF Geral'!A7 -> 45383 | B7: ='UF Geral'!B7/'UF Geral'!$AC7 -> 0.0022222732 | C7: ='UF Geral'!C7/'UF Geral'!$AC7 -> 0.012886197 | D7: ='UF Geral'!D7/'UF Geral'!$AC7 -> 0.011360173 | E7: ='UF Geral'!E7/'UF Geral'!$AC7 -> 0.0023425874 | F7: ='UF Geral'!F7/'UF Geral'!$AC7 -> 0.048182438 | G7: ='UF Geral'!G7/'UF Geral'!$AC7 -> 0.024004797 | H7: ='UF Geral'!H7/'UF Geral'!$AC7 -> 0.020281664 | I7: ='UF Geral'!I7/'UF Geral'!$AC7 -> 0.019157946 | ... AC7: ='UF Geral'!AC7/'UF Geral'!$AC7 -> 1
A8: ='UF Geral'!A8 -> 45413 | B8: ='UF Geral'!B8/'UF Geral'!$AC8 -> 0.0021853726 | C8: ='UF Geral'!C8/'UF Geral'!$AC8 -> 0.012590263 | D8: ='UF Geral'!D8/'UF Geral'!$AC8 -> 0.011432793 | E8: ='UF Geral'!E8/'UF Geral'!$AC8 -> 0.0023026004 | F8: ='UF Geral'!F8/'UF Geral'!$AC8 -> 0.047248656 | G8: ='UF Geral'!G8/'UF Geral'!$AC8 -> 0.023585304 | H8: ='UF Geral'!H8/'UF Geral'!$AC8 -> 0.020525813 | I8: ='UF Geral'!I8/'UF Geral'!$AC8 -> 0.018599113 | ... AC8: ='UF Geral'!AC8/'UF Geral'!$AC8 -> 1
A9: ='UF Geral'!A9 -> 45444 | B9: ='UF Geral'!B9/'UF Geral'!$AC9 -> 0.0021812609 | C9: ='UF Geral'!C9/'UF Geral'!$AC9 -> 0.01249936 | D9: ='UF Geral'!D9/'UF Geral'!$AC9 -> 0.011432166 | E9: ='UF Geral'!E9/'UF Geral'!$AC9 -> 0.0022868009 | F9: ='UF Geral'!F9/'UF Geral'!$AC9 -> 0.047036809 | G9: ='UF Geral'!G9/'UF Geral'!$AC9 -> 0.023516566 | H9: ='UF Geral'!H9/'UF Geral'!$AC9 -> 0.02064202 | I9: ='UF Geral'!I9/'UF Geral'!$AC9 -> 0.018641509 | ... AC9: ='UF Geral'!AC9/'UF Geral'!$AC9 -> 1
A10: ='UF Geral'!A10 -> 45474 | B10: ='UF Geral'!B10/'UF Geral'!$AC10 -> 0.0021704782 | C10: ='UF Geral'!C10/'UF Geral'!$AC10 -> 0.012096522 | D10: ='UF Geral'!D10/'UF Geral'!$AC10 -> 0.011464483 | E10: ='UF Geral'!E10/'UF Geral'!$AC10 -> 0.0022800379 | F10: ='UF Geral'!F10/'UF Geral'!$AC10 -> 0.046595694 | G10: ='UF Geral'!G10/'UF Geral'!$AC10 -> 0.02330598 | H10: ='UF Geral'!H10/'UF Geral'!$AC10 -> 0.020884926 | I10: ='UF Geral'!I10/'UF Geral'!$AC10 -> 0.018508525 | ... AC10: ='UF Geral'!AC10/'UF Geral'!$AC10 -> 1
A11: ='UF Geral'!A11 -> 45505 | B11: ='UF Geral'!B11/'UF Geral'!$AC11 -> 0.0021782741 | C11: ='UF Geral'!C11/'UF Geral'!$AC11 -> 0.011487419 | D11: ='UF Geral'!D11/'UF Geral'!$AC11 -> 0.011590303 | E11: ='UF Geral'!E11/'UF Geral'!$AC11 -> 0.0022816201 | F11: ='UF Geral'!F11/'UF Geral'!$AC11 -> 0.046582075 | G11: ='UF Geral'!G11/'UF Geral'!$AC11 -> 0.02324514 | H11: ='UF Geral'!H11/'UF Geral'!$AC11 -> 0.021134788 | I11: ='UF Geral'!I11/'UF Geral'!$AC11 -> 0.018501083 | ... AC11: ='UF Geral'!AC11/'UF Geral'!$AC11 -> 1
A12: ='UF Geral'!A12 -> 45536 | B12: ='UF Geral'!B12/'UF Geral'!$AC12 -> 0.0021622608 | C12: ='UF Geral'!C12/'UF Geral'!$AC12 -> 0.0115108 | D12: ='UF Geral'!D12/'UF Geral'!$AC12 -> 0.011573192 | E12: ='UF Geral'!E12/'UF Geral'!$AC12 -> 0.002269569 | F12: ='UF Geral'!F12/'UF Geral'!$AC12 -> 0.046838201 | G12: ='UF Geral'!G12/'UF Geral'!$AC12 -> 0.023250473 | H12: ='UF Geral'!H12/'UF Geral'!$AC12 -> 0.021276155 | I12: ='UF Geral'!I12/'UF Geral'!$AC12 -> 0.018574594 | ... AC12: ='UF Geral'!AC12/'UF Geral'!$AC12 -> 1
A13: ='UF Geral'!A13 -> 45566 | B13: ='UF Geral'!B13/'UF Geral'!$AC13 -> 0.0021640228 | C13: ='UF Geral'!C13/'UF Geral'!$AC13 -> 0.011451674 | D13: ='UF Geral'!D13/'UF Geral'!$AC13 -> 0.011565066 | E13: ='UF Geral'!E13/'UF Geral'!$AC13 -> 0.0022625188 | F13: ='UF Geral'!F13/'UF Geral'!$AC13 -> 0.047597862 | G13: ='UF Geral'!G13/'UF Geral'!$AC13 -> 0.023351443 | H13: ='UF Geral'!H13/'UF Geral'!$AC13 -> 0.021586724 | I13: ='UF Geral'!I13/'UF Geral'!$AC13 -> 0.018564814 | ... AC13: ='UF Geral'!AC13/'UF Geral'!$AC13 -> 1
A14: ='UF Geral'!A14 -> 45597 | B14: ='UF Geral'!B14/'UF Geral'!$AC14 -> 0.0020352514 | C14: ='UF Geral'!C14/'UF Geral'!$AC14 -> 0.011425946 | D14: ='UF Geral'!D14/'UF Geral'!$AC14 -> 0.011648958 | E14: ='UF Geral'!E14/'UF Geral'!$AC14 -> 0.0022299687 | F14: ='UF Geral'!F14/'UF Geral'!$AC14 -> 0.046247624 | G14: ='UF Geral'!G14/'UF Geral'!$AC14 -> 0.023309022 | H14: ='UF Geral'!H14/'UF Geral'!$AC14 -> 0.021729074 | I14: ='UF Geral'!I14/'UF Geral'!$AC14 -> 0.018555031 | ... AC14: ='UF Geral'!AC14/'UF Geral'!$AC14 -> 1
A15: ='UF Geral'!A15 -> 45627 | B15: ='UF Geral'!B15/'UF Geral'!$AC15 -> 0.0020170869 | C15: ='UF Geral'!C15/'UF Geral'!$AC15 -> 0.011341368 | D15: ='UF Geral'!D15/'UF Geral'!$AC15 -> 0.011525253 | E15: ='UF Geral'!E15/'UF Geral'!$AC15 -> 0.0022284168 | F15: ='UF Geral'!F15/'UF Geral'!$AC15 -> 0.045923682 | G15: ='UF Geral'!G15/'UF Geral'!$AC15 -> 0.023391896 | H15: ='UF Geral'!H15/'UF Geral'!$AC15 -> 0.021623952 | I15: ='UF Geral'!I15/'UF Geral'!$AC15 -> 0.018058943 | ... AC15: ='UF Geral'!AC15/'UF Geral'!$AC15 -> 1
... A34: ='UF Geral'!A34 -> 46204 | B34: ='UF Geral'!B34/'UF Geral'!$AC34 -> 0.0015293922 | C34: ='UF Geral'!C34/'UF Geral'!$AC34 -> 0.0065790648 | D34: ='UF Geral'!D34/'UF Geral'!$AC34 -> 0.016412981 | E34: ='UF Geral'!E34/'UF Geral'!$AC34 -> 0.001730381 | F34: ='UF Geral'!F34/'UF Geral'!$AC34 -> 0.036552153 | G34: ='UF Geral'!G34/'UF Geral'!$AC34 -> 0.020868501 | H34: ='UF Geral'!H34/'UF Geral'!$AC34 -> 0.024539294 | I34: ='UF Geral'!I34/'UF Geral'!$AC34 -> 0.015005373 | ... AC34: ='UF Geral'!AC34/'UF Geral'!$AC34 -> 1
A35: ='UF Geral'!A35 -> 46235
A36: ='UF Geral'!A36 -> 46266
A37: ='UF Geral'!A37 -> 46296
A38: ='UF Geral'!A38 -> 46327
A39: ='UF Geral'!A39 -> 46357

Sheet UF Var.Mensal
A2: Indicador Serasa Experian de Inadimplência das Micro e Pequenas Empresas por Unidades da Federação - Variação Mensal
A3: UF | B3: AC | C3: AL | D3: AM | E3: AP | F3: BA | G3: CE | H3: DF | I3: ES | J3: GO | K3: MA | L3: MG | M3: MS | N3: MT | O3: PA | P3: PB | Q3: PE | R3: PI | S3: PR | T3: RJ | U3: RN | V3: RO | W3: RR | X3: RS | Y3: SC | Z3: SE | AA3: SP | AB3: TO | AC3: Total Geral
A4: ='UF Geral'!A4 -> 45292 | B4: n.d. | C4: n.d. | D4: n.d. | E4: n.d. | F4: n.d. | G4: n.d. | H4: n.d. | I4: n.d. | J4: n.d. | K4: n.d. | L4: n.d. | M4: n.d. | N4: n.d. | O4: n.d. | P4: n.d. | Q4: n.d. | R4: n.d. | S4: n.d. | T4: n.d. | U4: n.d. | V4: n.d. | W4: n.d. | X4: n.d. | Y4: n.d. | Z4: n.d. | AA4: n.d. | AB4: n.d. | AC4: n.d.
A5: ='UF Geral'!A5 -> 45323 | B5: ='UF Geral'!B5/'UF Geral'!B4-1 -> 0.00028663561 | C5: ='UF Geral'!C5/'UF Geral'!C4-1 -> 0.031814833 | D5: ='UF Geral'!D5/'UF Geral'!D4-1 -> -0.029974571 | E5: ='UF Geral'!E5/'UF Geral'!E4-1 -> 0.0026536028 | F5: ='UF Geral'!F5/'UF Geral'!F4-1 -> 0.0096813299 | G5: ='UF Geral'!G5/'UF Geral'!G4-1 -> -0.0053256916 | H5: ='UF Geral'!H5/'UF Geral'!H4-1 -> 0.0048043305 | I5: ='UF Geral'!I5/'UF Geral'!I4-1 -> 0.013269364 | ... AC5: ='UF Geral'!AC5/'UF Geral'!AC4-1 -> -0.0025226538
A6: ='UF Geral'!A6 -> 45352 | B6: ='UF Geral'!B6/'UF Geral'!B5-1 -> 0.0040117487 | C6: ='UF Geral'!C6/'UF Geral'!C5-1 -> 0.020278231 | D6: ='UF Geral'!D6/'UF Geral'!D5-1 -> 0.0060483576 | E6: ='UF Geral'!E6/'UF Geral'!E5-1 -> 0.0011536374 | F6: ='UF Geral'!F6/'UF Geral'!F5-1 -> 0.009532117 | G6: ='UF Geral'!G6/'UF Geral'!G5-1 -> 0.015313966 | H6: ='UF Geral'!H6/'UF Geral'!H5-1 -> 0.033101088 | I6: ='UF Geral'!I6/'UF Geral'!I5-1 -> 0.010084034 | ... AC6: ='UF Geral'!AC6/'UF Geral'!AC5-1 -> 0.003467455
A7: ='UF Geral'!A7 -> 45383 | B7: ='UF Geral'!B7/'UF Geral'!B6-1 -> 0.0082054941 | C7: ='UF Geral'!C7/'UF Geral'!C6-1 -> -0.044322622 | D7: ='UF Geral'!D7/'UF Geral'!D6-1 -> 0.051473157 | E7: ='UF Geral'!E7/'UF Geral'!E6-1 -> 0.009625161 | F7: ='UF Geral'!F7/'UF Geral'!F6-1 -> 0.0065050052 | G7: ='UF Geral'!G7/'UF Geral'!G6-1 -> 0.0048586834 | H7: ='UF Geral'!H7/'UF Geral'!H6-1 -> 0.02198377 | I7: ='UF Geral'!I7/'UF Geral'!I6-1 -> 0.028852082 | ... AC7: ='UF Geral'!AC7/'UF Geral'!AC6-1 -> 0.010398837
A8: ='UF Geral'!A8 -> 45413 | B8: ='UF Geral'!B8/'UF Geral'!B7-1 -> 0.0026893135 | C8: ='UF Geral'!C8/'UF Geral'!C7-1 -> -0.0037956917 | D8: ='UF Geral'!D8/'UF Geral'!D7-1 -> 0.026138 | E8: ='UF Geral'!E8/'UF Geral'!E7-1 -> 0.0022155086 | F8: ='UF Geral'!F8/'UF Geral'!F7-1 -> -0.00014035729 | G8: ='UF Geral'!G8/'UF Geral'!G7-1 -> 0.001801731 | H8: ='UF Geral'!H8/'UF Geral'!H7-1 -> 0.031894105 | I8: ='UF Geral'!I8/'UF Geral'!I7-1 -> -0.010122072 | ... AC8: ='UF Geral'!AC8/'UF Geral'!AC7-1 -> 0.019620015
A9: ='UF Geral'!A9 -> 45444 | B9: ='UF Geral'!B9/'UF Geral'!B8-1 -> 0.0050818746 | C9: ='UF Geral'!C9/'UF Geral'!C8-1 -> -0.00029403117 | D9: ='UF Geral'!D9/'UF Geral'!D8-1 -> 0.0069212089 | E9: ='UF Geral'!E9/'UF Geral'!E8-1 -> 6.698821e-05 | F9: ='UF Geral'!F9/'UF Geral'!F8-1 -> 0.0024614943 | G9: ='UF Geral'!G9/'UF Geral'!G8-1 -> 0.0040416988 | H9: ='UF Geral'!H9/'UF Geral'!H8-1 -> 0.012677443 | I9: ='UF Geral'!I9/'UF Geral'!I8-1 -> 0.0092718527 | ... AC9: ='UF Geral'!AC9/'UF Geral'!AC8-1 -> 0.0069764411
A10: ='UF Geral'!A10 -> 45474 | B10: ='UF Geral'!B10/'UF Geral'!B9-1 -> -0.0066713483 | C10: ='UF Geral'!C10/'UF Geral'!C9-1 -> -0.033909314 | D10: ='UF Geral'!D10/'UF Geral'!D9-1 -> 0.0010853108 | E10: ='UF Geral'!E10/'UF Geral'!E9-1 -> -0.0046888606 | F10: ='UF Geral'!F10/'UF Geral'!F9-1 -> -0.011098374 | G10: ='UF Geral'!G10/'UF Geral'!G9-1 -> -0.010675855 | H10: ='UF Geral'!H10/'UF Geral'!H9-1 -> 0.010010537 | I10: ='UF Geral'!I10/'UF Geral'!I9-1 -> -0.0088579927 | ... AC10: ='UF Geral'!AC10/'UF Geral'!AC9-1 -> -0.0017365839
A11: ='UF Geral'!A11 -> 45505 | B11: ='UF Geral'!B11/'UF Geral'!B10-1 -> -0.00014139272 | C11: ='UF Geral'!C11/'UF Geral'!C10-1 -> -0.053886063 | D11: ='UF Geral'!D11/'UF Geral'!D10-1 -> 0.0072141767 | E11: ='UF Geral'!E11/'UF Geral'!E10-1 -> -0.0030284676 | F11: ='UF Geral'!F11/'UF Geral'!F10-1 -> -0.0040110122 | G11: ='UF Geral'!G11/'UF Geral'!G10-1 -> -0.0063205715 | H11: ='UF Geral'!H11/'UF Geral'!H10-1 -> 0.0081994313 | I11: ='UF Geral'!I11/'UF Geral'!I10-1 -> -0.004120378 | ... AC11: ='UF Geral'!AC11/'UF Geral'!AC10-1 -> -0.0037198114
A12: ='UF Geral'!A12 -> 45536 | B12: ='UF Geral'!B12/'UF Geral'!B11-1 -> -0.0026868415 | C12: ='UF Geral'!C12/'UF Geral'!C11-1 -> 0.0067439834 | D12: ='UF Geral'!D12/'UF Geral'!D11-1 -> 0.0032158186 | E12: ='UF Geral'!E12/'UF Geral'!E11-1 -> -0.00060753341 | F12: ='UF Geral'!F12/'UF Geral'!F11-1 -> 0.010223313 | G12: ='UF Geral'!G12/'UF Geral'!G11-1 -> 0.0049296008 | H12: ='UF Geral'!H12/'UF Geral'!H11-1 -> 0.011419368 | I12: ='UF Geral'!I12/'UF Geral'!I11-1 -> 0.0086910916 | ... AC12: ='UF Geral'!AC12/'UF Geral'!AC11-1 -> 0.0046990838
A13: ='UF Geral'!A13 -> 45566 | B13: ='UF Geral'!B13/'UF Geral'!B12-1 -> 0.0093583836 | C13: ='UF Geral'!C13/'UF Geral'!C12-1 -> 0.0033560622 | D13: ='UF Geral'!D13/'UF Geral'!D12-1 -> 0.007828333 | E13: ='UF Geral'!E13/'UF Geral'!E12-1 -> 0.0054035799 | F13: ='UF Geral'!F13/'UF Geral'!F12-1 -> 0.024893794 | G13: ='UF Geral'!G13/'UF Geral'!G12-1 -> 0.012916285 | H13: ='UF Geral'!H13/'UF Geral'!H12-1 -> 0.02325816 | I13: ='UF Geral'!I13/'UF Geral'!I12-1 -> 0.00800548 | ... AC13: ='UF Geral'!AC13/'UF Geral'!AC12-1 -> 0.0085365227
A14: ='UF Geral'!A14 -> 45597 | B14: ='UF Geral'!B14/'UF Geral'!B13-1 -> -0.060265505 | C14: ='UF Geral'!C14/'UF Geral'!C13-1 -> -0.0030528272 | D14: ='UF Geral'!D14/'UF Geral'!D13-1 -> 0.006440081 | E14: ='UF Geral'!E14/'UF Geral'!E13-1 -> -0.01518307 | F14: ='UF Geral'!F14/'UF Geral'!F13-1 -> -0.029152722 | G14: ='UF Geral'!G14/'UF Geral'!G13-1 -> -0.0026232197 | H14: ='UF Geral'!H14/'UF Geral'!H13-1 -> 0.0057809573 | I14: ='UF Geral'!I14/'UF Geral'!I13-1 -> -0.0013345669 | ... AC14: ='UF Geral'!AC14/'UF Geral'!AC13-1 -> -0.00080803155
A15: ='UF Geral'!A15 -> 45627 | B15: ='UF Geral'!B15/'UF Geral'!B14-1 -> -0.0112116 | C15: ='UF Geral'!C15/'UF Geral'!C14-1 -> -0.0096924511 | D15: ='UF Geral'!D15/'UF Geral'!D14-1 -> -0.012902215 | E15: ='UF Geral'!E15/'UF Geral'!E14-1 -> -0.003001569 | F15: ='UF Geral'!F15/'UF Geral'!F14-1 -> -0.009295594 | G15: ='UF Geral'!G15/'UF Geral'!G14-1 -> 0.0012400065 | H15: ='UF Geral'!H15/'UF Geral'!H14-1 -> -0.007133906 | I15: ='UF Geral'!I15/'UF Geral'!I14-1 -> -0.028981586 | ... AC15: ='UF Geral'!AC15/'UF Geral'!AC14-1 -> -0.0023072471
A16: ='UF Geral'!A16 -> 45658 | B16: ='UF Geral'!B16/'UF Geral'!B15-1 -> 0.023131 | C16: ='UF Geral'!C16/'UF Geral'!C15-1 -> 0.020851819 | D16: ='UF Geral'!D16/'UF Geral'!D15-1 -> 0.034370535 | E16: ='UF Geral'!E16/'UF Geral'!E15-1 -> 0.015600411 | F16: ='UF Geral'!F16/'UF Geral'!F15-1 -> 0.014993907 | G16: ='UF Geral'!G16/'UF Geral'!G15-1 -> 0.021510283 | H16: ='UF Geral'!H16/'UF Geral'!H15-1 -> 0.022895219 | I16: ='UF Geral'!I16/'UF Geral'!I15-1 -> 0.012563429 | ... AC16: ='UF Geral'!AC16/'UF Geral'!AC15-1 -> 0.015567203
... A34: ='UF Geral'!A34 -> 46204 | B34: ='UF Geral'!B34/'UF Geral'!B33-1 -> -0.0015691549 | C34: ='UF Geral'!C34/'UF Geral'!C33-1 -> 0.0014111744 | D34: ='UF Geral'!D34/'UF Geral'!D33-1 -> 0.006139403 | E34: ='UF Geral'!E34/'UF Geral'!E33-1 -> -0.00026451528 | F34: ='UF Geral'!F34/'UF Geral'!F33-1 -> 0.0033240022 | G34: ='UF Geral'!G34/'UF Geral'!G33-1 -> 0.0026341115 | H34: ='UF Geral'!H34/'UF Geral'!H33-1 -> 0.0050440889 | I34: ='UF Geral'!I34/'UF Geral'!I33-1 -> 0.005190842 | ... AC34: ='UF Geral'!AC34/'UF Geral'!AC33-1 -> 0.0058707234
A35: ='UF Geral'!A35 -> 46235
A36: ='UF Geral'!A36 -> 46266
A37: ='UF Geral'!A37 -> 46296
A38: ='UF Geral'!A38 -> 46327
A39: ='UF Geral'!A39 -> 46357

Sheet UF Var.Anual
B2: Indicador Serasa Experian de Inadimplência das Micro e Pequenas Empresas por Unidades da Federação - Variação Anual
A3: UF | B3: AC | C3: AL | D3: AM | E3: AP | F3: BA | G3: CE | H3: DF | I3: ES | J3: GO | K3: MA | L3: MG | M3: MS | N3: MT | O3: PA | P3: PB | Q3: PE | R3: PI | S3: PR | T3: RJ | U3: RN | V3: RO | W3: RR | X3: RS | Y3: SC | Z3: SE | AA3: SP | AB3: TO | AC3: Total Geral
A4: ='UF Geral'!A4 -> 45292 | B4: n.d. | C4: n.d. | D4: n.d. | E4: n.d. | F4: n.d. | G4: n.d. | H4: n.d. | I4: n.d. | J4: n.d. | K4: n.d. | L4: n.d. | M4: n.d. | N4: n.d. | O4: n.d. | P4: n.d. | Q4: n.d. | R4: n.d. | S4: n.d. | T4: n.d. | U4: n.d. | V4: n.d. | W4: n.d. | X4: n.d. | Y4: n.d. | Z4: n.d. | AA4: n.d. | AB4: n.d. | AC4: n.d.
A5: ='UF Geral'!A5 -> 45323 | B5: n.d. | C5: n.d. | D5: n.d. | E5: n.d. | F5: n.d. | G5: n.d. | H5: n.d. | I5: n.d. | J5: n.d. | K5: n.d. | L5: n.d. | M5: n.d. | N5: n.d. | O5: n.d. | P5: n.d. | Q5: n.d. | R5: n.d. | S5: n.d. | T5: n.d. | U5: n.d. | V5: n.d. | W5: n.d. | X5: n.d. | Y5: n.d. | Z5: n.d. | AA5: n.d. | AB5: n.d. | AC5: n.d.
A6: ='UF Geral'!A6 -> 45352 | B6: n.d. | C6: n.d. | D6: n.d. | E6: n.d. | F6: n.d. | G6: n.d. | H6: n.d. | I6: n.d. | J6: n.d. | K6: n.d. | L6: n.d. | M6: n.d. | N6: n.d. | O6: n.d. | P6: n.d. | Q6: n.d. | R6: n.d. | S6: n.d. | T6: n.d. | U6: n.d. | V6: n.d. | W6: n.d. | X6: n.d. | Y6: n.d. | Z6: n.d. | AA6: n.d. | AB6: n.d. | AC6: n.d.
A7: ='UF Geral'!A7 -> 45383 | B7: n.d. | C7: n.d. | D7: n.d. | E7: n.d. | F7: n.d. | G7: n.d. | H7: n.d. | I7: n.d. | J7: n.d. | K7: n.d. | L7: n.d. | M7: n.d. | N7: n.d. | O7: n.d. | P7: n.d. | Q7: n.d. | R7: n.d. | S7: n.d. | T7: n.d. | U7: n.d. | V7: n.d. | W7: n.d. | X7: n.d. | Y7: n.d. | Z7: n.d. | AA7: n.d. | AB7: n.d. | AC7: n.d.
A8: ='UF Geral'!A8 -> 45413 | B8: n.d. | C8: n.d. | D8: n.d. | E8: n.d. | F8: n.d. | G8: n.d. | H8: n.d. | I8: n.d. | J8: n.d. | K8: n.d. | L8: n.d. | M8: n.d. | N8: n.d. | O8: n.d. | P8: n.d. | Q8: n.d. | R8: n.d. | S8: n.d. | T8: n.d. | U8: n.d. | V8: n.d. | W8: n.d. | X8: n.d. | Y8: n.d. | Z8: n.d. | AA8: n.d. | AB8: n.d. | AC8: n.d.
A9: ='UF Geral'!A9 -> 45444 | B9: n.d. | C9: n.d. | D9: n.d. | E9: n.d. | F9: n.d. | G9: n.d. | H9: n.d. | I9: n.d. | J9: n.d. | K9: n.d. | L9: n.d. | M9: n.d. | N9: n.d. | O9: n.d. | P9: n.d. | Q9: n.d. | R9: n.d. | S9: n.d. | T9: n.d. | U9: n.d. | V9: n.d. | W9: n.d. | X9: n.d. | Y9: n.d. | Z9: n.d. | AA9: n.d. | AB9: n.d. | AC9: n.d.
A10: ='UF Geral'!A10 -> 45474 | B10: n.d. | C10: n.d. | D10: n.d. | E10: n.d. | F10: n.d. | G10: n.d. | H10: n.d. | I10: n.d. | J10: n.d. | K10: n.d. | L10: n.d. | M10: n.d. | N10: n.d. | O10: n.d. | P10: n.d. | Q10: n.d. | R10: n.d. | S10: n.d. | T10: n.d. | U10: n.d. | V10: n.d. | W10: n.d. | X10: n.d. | Y10: n.d. | Z10: n.d. | AA10: n.d. | AB10: n.d. | AC10: n.d.
A11: ='UF Geral'!A11 -> 45505 | B11: n.d. | C11: n.d. | D11: n.d. | E11: n.d. | F11: n.d. | G11: n.d. | H11: n.d. | I11: n.d. | J11: n.d. | K11: n.d. | L11: n.d. | M11: n.d. | N11: n.d. | O11: n.d. | P11: n.d. | Q11: n.d. | R11: n.d. | S11: n.d. | T11: n.d. | U11: n.d. | V11: n.d. | W11: n.d. | X11: n.d. | Y11: n.d. | Z11: n.d. | AA11: n.d. | AB11: n.d. | AC11: n.d.
A12: ='UF Geral'!A12 -> 45536 | B12: n.d. | C12: n.d. | D12: n.d. | E12: n.d. | F12: n.d. | G12: n.d. | H12: n.d. | I12: n.d. | J12: n.d. | K12: n.d. | L12: n.d. | M12: n.d. | N12: n.d. | O12: n.d. | P12: n.d. | Q12: n.d. | R12: n.d. | S12: n.d. | T12: n.d. | U12: n.d. | V12: n.d. | W12: n.d. | X12: n.d. | Y12: n.d. | Z12: n.d. | AA12: n.d. | AB12: n.d. | AC12: n.d.
A13: ='UF Geral'!A13 -> 45566 | B13: n.d. | C13: n.d. | D13: n.d. | E13: n.d. | F13: n.d. | G13: n.d. | H13: n.d. | I13: n.d. | J13: n.d. | K13: n.d. | L13: n.d. | M13: n.d. | N13: n.d. | O13: n.d. | P13: n.d. | Q13: n.d. | R13: n.d. | S13: n.d. | T13: n.d. | U13: n.d. | V13: n.d. | W13: n.d. | X13: n.d. | Y13: n.d. | Z13: n.d. | AA13: n.d. | AB13: n.d. | AC13: n.d.
A14: ='UF Geral'!A14 -> 45597 | B14: n.d. | C14: n.d. | D14: n.d. | E14: n.d. | F14: n.d. | G14: n.d. | H14: n.d. | I14: n.d. | J14: n.d. | K14: n.d. | L14: n.d. | M14: n.d. | N14: n.d. | O14: n.d. | P14: n.d. | Q14: n.d. | R14: n.d. | S14: n.d. | T14: n.d. | U14: n.d. | V14: n.d. | W14: n.d. | X14: n.d. | Y14: n.d. | Z14: n.d. | AA14: n.d. | AB14: n.d. | AC14: n.d.
A15: ='UF Geral'!A15 -> 45627 | B15: n.d. | C15: n.d. | D15: n.d. | E15: n.d. | F15: n.d. | G15: n.d. | H15: n.d. | I15: n.d. | J15: n.d. | K15: n.d. | L15: n.d. | M15: n.d. | N15: n.d. | O15: n.d. | P15: n.d. | Q15: n.d. | R15: n.d. | S15: n.d. | T15: n.d. | U15: n.d. | V15: n.d. | W15: n.d. | X15: n.d. | Y15: n.d. | Z15: n.d. | AA15: n.d. | AB15: n.d. | AC15: n.d.
A16: ='UF Geral'!A16 -> 45658 | B16: ='UF Geral'!B16/'UF Geral'!B4-1 -> -0.03009674 | C16: ='UF Geral'!C16/'UF Geral'!C4-1 -> -0.067620334 | D16: ='UF Geral'!D16/'UF Geral'!D4-1 -> 0.11070703 | E16: ='UF Geral'!E16/'UF Geral'!E4-1 -> 0.0099340001 | F16: ='UF Geral'!F16/'UF Geral'!F4-1 -> 0.023739518 | G16: ='UF Geral'!G16/'UF Geral'!G4-1 -> 0.041967248 | H16: ='UF Geral'!H16/'UF Geral'!H4-1 -> 0.19340721 | I16: ='UF Geral'!I16/'UF Geral'!I4-1 -> 0.036713347 | ... AC16: ='UF Geral'!AC16/'UF Geral'!AC4-1 -> 0.059413586
A17: ='UF Geral'!A17 -> 45689 | B17: ='UF Geral'!B17/'UF Geral'!B5-1 -> -0.0077369439 | C17: ='UF Geral'!C17/'UF Geral'!C5-1 -> -0.088645857 | D17: ='UF Geral'!D17/'UF Geral'!D5-1 -> 0.18478977 | E17: ='UF Geral'!E17/'UF Geral'!E5-1 -> 0.030876764 | F17: ='UF Geral'!F17/'UF Geral'!F5-1 -> 0.029959503 | G17: ='UF Geral'!G17/'UF Geral'!G5-1 -> 0.056082138 | H17: ='UF Geral'!H17/'UF Geral'!H5-1 -> 0.21980334 | I17: ='UF Geral'!I17/'UF Geral'!I5-1 -> 0.031156422 | ... AC17: ='UF Geral'!AC17/'UF Geral'!AC5-1 -> 0.082789655
A18: ='UF Geral'!A18 -> 45717 | B18: ='UF Geral'!B18/'UF Geral'!B6-1 -> 0.013699608 | C18: ='UF Geral'!C18/'UF Geral'!C6-1 -> -0.11081822 | D18: ='UF Geral'!D18/'UF Geral'!D6-1 -> 0.21205019 | E18: ='UF Geral'!E18/'UF Geral'!E6-1 -> 0.044668881 | F18: ='UF Geral'!F18/'UF Geral'!F6-1 -> 0.038001715 | G18: ='UF Geral'!G18/'UF Geral'!G6-1 -> 0.069976892 | H18: ='UF Geral'!H18/'UF Geral'!H6-1 -> 0.21179389 | I18: ='UF Geral'!I18/'UF Geral'!I6-1 -> 0.028303082 | ... AC18: ='UF Geral'!AC18/'UF Geral'!AC6-1 -> 0.10126658
A19: ='UF Geral'!A19 -> 45748 | B19: ='UF Geral'!B19/'UF Geral'!B7-1 -> 0.037650389 | C19: ='UF Geral'!C19/'UF Geral'!C7-1 -> -0.064270458 | D19: ='UF Geral'!D19/'UF Geral'!D7-1 -> 0.19269853 | E19: ='UF Geral'!E19/'UF Geral'!E7-1 -> 0.074588788 | F19: ='UF Geral'!F19/'UF Geral'!F7-1 -> 0.050835452 | G19: ='UF Geral'!G19/'UF Geral'!G7-1 -> 0.09432553 | H19: ='UF Geral'!H19/'UF Geral'!H7-1 -> 0.23204454 | I19: ='UF Geral'!I19/'UF Geral'!I7-1 -> 0.022567378 | ... AC19: ='UF Geral'!AC19/'UF Geral'!AC7-1 -> 0.12085203
A20: ='UF Geral'!A20 -> 45778 | B20: ='UF Geral'!B20/'UF Geral'!B8-1 -> 0.053783173 | C20: ='UF Geral'!C20/'UF Geral'!C8-1 -> -0.055265608 | D20: ='UF Geral'!D20/'UF Geral'!D8-1 -> 0.19558824 | E20: ='UF Geral'!E20/'UF Geral'!E8-1 -> 0.085878885 | F20: ='UF Geral'!F20/'UF Geral'!F8-1 -> 0.065356917 | G20: ='UF Geral'!G20/'UF Geral'!G8-1 -> 0.11342917 | H20: ='UF Geral'!H20/'UF Geral'!H8-1 -> 0.221348 | I20: ='UF Geral'!I20/'UF Geral'!I8-1 -> 0.025286117 | ... AC20: ='UF Geral'!AC20/'UF Geral'!AC8-1 -> 0.12201962
A21: ='UF Geral'!A21 -> 45809 | B21: ='UF Geral'!B21/'UF Geral'!B9-1 -> 0.052668539 | C21: ='UF Geral'!C21/'UF Geral'!C9-1 -> -0.053406863 | D21: ='UF Geral'!D21/'UF Geral'!D9-1 -> 0.21115324 | E21: ='UF Geral'!E21/'UF Geral'!E9-1 -> 0.086743921 | F21: ='UF Geral'!F21/'UF Geral'!F9-1 -> 0.063418351 | G21: ='UF Geral'!G21/'UF Geral'!G9-1 -> 0.12071728 | H21: ='UF Geral'!H21/'UF Geral'!H9-1 -> 0.22769706 | I21: ='UF Geral'!I21/'UF Geral'!I9-1 -> 0.019203274 | ... AC21: ='UF Geral'!AC21/'UF Geral'!AC9-1 -> 0.13057328
